Workbook

Sheet LS_RPRO
A1: Branch:
A2: 46296
A3: .
A4: DAYS | E4: Details of Discount | H4: NO. | K4: NO. OF STRING | M4: ENTERING | O4: CHARGE | P4: GIFT | Q4: OTHER COLLECTION | U4: CHECKS | V4: OTHER DISBURSEMENT | Z4: CASH DECLARED and DEPOSITED | AA4: CASH SALES | AB4: Calculated Cash Fr. Manual and OutSale | AC4: Cash Fr. Manual and OutSale | AD4: Over/(Short)
B5: GROSS | C5: DISCOUNT | D5: NET SALES | E5: ÀPPROVED DISC | F5: DISC W/O APPROVAL | G5: DEL. FEE | H5: CUSTOMER | I5: SHORTAGE | J5: OVERAGE | K5: TENNIS | L5: BADMIN2N | M5: CUSTOMER | O5: SALES | P5: CHECK | Q5: GC ISSUED-cash | R5: GC ISSUED-card | S5: DOWNPAYMENT | T5: ADV | V5: COD | W5: CASH ADVANCE | X5: (ADV) | Y5: CWT | AA5: AVAILABLE
A6: =A2+0 -> 46296 | B6: =102690.45+70551.9 -> 173242.35 | C6: 0 | D6: =+B6-C6 -> 173242.35 | F6: =+C6-E6 -> 0 | I6: =SUMIF(AB6,"<.01") -> 0 | J6: =SUMIF(AB6,">.01") -> 3 | K6: 0 | L6: 0 | M6: 359 | O6: =83892.7+53912.65 -> 137805.35 | X6: =4636 -> 4636 | Z6: =18800+12004 -> 30804 | AA6: =D6-O6-P6+Q6+S6+T6-U6-V6-W6-X6-Y6 -> 30801 | AB6: =Z6-AA6 -> 3 | AC6: =[1]MANUAL!X6+[1]OUTSALE!X6 -> 0 | AD6: =AB6-AC6 -> 3 | AF6: =O6+P6+U6+V6+W6+X6+Y6-Q6-R6-S6-T6 -> 142441.35
A7: =A6+1 -> 46297 | B7: =95054.25+113718.25 -> 208772.5 | C7: =169.8 -> 169.8 | D7: =+B7-C7 -> 208602.7 | E7: 169.8 | F7: =+C7-E7 -> 0 | H7: =45+56 -> 101 | I7: =SUMIF(AB7,"<.01") -> 0 | J7: =SUMIF(AB7,">.01") -> 4.05 | K7: 0 | L7: 2 | M7: 446 | O7: =71488.5+100077.25+236 -> 171801.75 | T7: 4636 | W7: 2363 | Z7: =23400+15678 -> 39078 | AA7: =D7-O7-P7+Q7+S7+T7-U7-V7-W7-X7-Y7 -> 39073.95 | AB7: =Z7-AA7 -> 4.05 | AC7: =[1]MANUAL!X7+[1]OUTSALE!X7 -> 0 | AD7: =AB7-AC7 -> 4.05 | AF7: =O7+P7+U7+V7+W7+X7+Y7-Q7-R7-S7-T7 -> 169528.75
A8: =A7+1 -> 46298 | B8: =355395.97+400 -> 355795.97 | C8: =349.5+359.46 -> 708.96 | D8: =+B8-C8 -> 355087.01 | E8: 708.96 | F8: =+C8-E8 -> 0 | H8: 138 | I8: =SUMIF(AB8,"<.01") -> 0 | J8: =SUMIF(AB8,">.01") -> 5.74 | K8: 4 | L8: 5 | M8: 976 | O8: =279997.55+5583.2 -> 285580.75 | V8: 400 | Z8: =69112 -> 69112 | AA8: =D8-O8-P8+Q8+S8+T8-U8-V8-W8-X8-Y8 -> 69106.26 | AB8: =Z8-AA8 -> 5.74 | AC8: =[1]MANUAL!X8+[1]OUTSALE!X8 -> 0 | AD8: =AB8-AC8 -> 5.74 | AF8: =O8+P8+U8+V8+W8+X8+Y8-Q8-R8-S8-T8 -> 285980.75
A9: =A8+1 -> 46299 | B9: =117294.75+182731.95 -> 300026.7 | C9: =109+199+1074+669+129.5 -> 2180.5 | D9: =+B9-C9 -> 297846.2 | E9: 2180.5 | F9: =+C9-E9 -> 0 | H9: =58+72 -> 130 | I9: =SUMIF(AB9,"<.01") -> 0 | J9: =SUMIF(AB9,">.01") -> 4 | K9: 0 | L9: 17 | M9: 883 | O9: =97328.25+145749.45 -> 243077.7 | Q9: 3100 | X9: =3040+3040 -> 6080 | Z9: =19658.5+32134 -> 51792.5 | AA9: =D9-O9-P9+Q9+S9+T9-U9-V9-W9-X9-Y9 -> 51788.5 | AB9: =Z9-AA9 -> 4 | AC9: =[1]MANUAL!X9+[1]OUTSALE!X9 -> 0 | AD9: =AB9-AC9 -> 4 | AF9: =O9+P9+U9+V9+W9+X9+Y9-Q9-R9-S9-T9 -> 246057.7
A10: =A9+1 -> 46300 | B10: =99966+114263.95+400 -> 214629.95 | C10: =299.6+470.46+826 -> 1596.06 | D10: =+B10-C10 -> 213033.89 | E10: 1596.06 | F10: =+C10-E10 -> 0 | H10: =33+42 -> 75 | I10: =SUMIF(AB10,"<.01") -> -47.2 | J10: =SUMIF(AB10,">.01") -> 0 | K10: 5 | L10: 1 | M10: 687 | O10: =74414.5+94015.19 -> 168429.69 | X10: 5280 | Z10: =25554+13723 -> 39277 | AA10: =D10-O10-P10+Q10+S10+T10-U10-V10-W10-X10-Y10 -> 39324.2 | AB10: =Z10-AA10 -> -47.2 | AC10: =MANUAL!X10+OUTSALE!X10 -> 0 | AD10: =AB10-AC10 -> -47.2 | AF10: =O10+P10+U10+V10+W10+X10+Y10-Q10-R10-S10-T10 -> 173709.69
A11: =A10+1 -> 46301 | B11: =72673.5+79201 -> 151874.5 | C11: =222.5+106.25 -> 328.75 | D11: =+B11-C11 -> 151545.75 | E11: 328.75 | F11: =+C11-E11 -> 0 | H11: =33+39 -> 72 | I11: =SUMIF(AB11,"<.01") -> 0 | J11: =SUMIF(AB11,">.01") -> 0 | K11: 1 | L11: 1 | M11: 333 | O11: =65038.5+78559.25 -> 143597.75 | T11: 11360 | Z11: =7635+11673 -> 19308 | AA11: =D11-O11-P11+Q11+S11+T11-U11-V11-W11-X11-Y11 -> 19308 | AB11: =Z11-AA11 -> 0 | AC11: =MANUAL!X11+OUTSALE!X11 -> 0 | AD11: =AB11-AC11 -> 0 | AF11: =O11+P11+U11+V11+W11+X11+Y11-Q11-R11-S11-T11 -> 132237.75
A12: =A11+1 -> 46302 | B12: =40683+75860.95 -> 116543.95 | C12: =328+119+319.5+199.8 -> 966.3 | D12: =+B12-C12 -> 115577.65 | E12: 966.3 | F12: =+C12-E12 -> 0 | H12: =23+27 -> 50 | I12: =SUMIF(AB12,"<.01") -> 0 | J12: =SUMIF(AB12,">.01") -> 1 | K12: 0 | L12: 0 | M12: 316 | O12: =16052+7208+718+1493.5+56438.9 -> 81910.4 | Z12: =14446+19222.25 -> 33668.25 | AA12: =D12-O12-P12+Q12+S12+T12-U12-V12-W12-X12-Y12 -> 33667.25 | AB12: =Z12-AA12 -> 1 | AC12: =MANUAL!X12+OUTSALE!X12 -> 0 | AD12: =AB12-AC12 -> 1 | AF12: =O12+P12+U12+V12+W12+X12+Y12-Q12-R12-S12-T12 -> 81910.4
A13: =A12+1 -> 46303 | B13: =90672.5+56282 -> 146954.5 | C13: =749.25+519 -> 1268.25 | D13: =+B13-C13 -> 145686.25 | E13: 1268.25 | F13: =+C13-E13 -> 0 | H13: =31+36 -> 67 | I13: =SUMIF(AB13,"<.01") -> 0 | J13: =SUMIF(AB13,">.01") -> 3 | K13: 0 | L13: 0 | M13: 478 | O13: =83072.25+36993 -> 120065.25 | Z13: =6332+19292 -> 25624 | AA13: =D13-O13-P13+Q13+S13+T13-U13-V13-W13-X13-Y13 -> 25621 | AB13: =Z13-AA13 -> 3 | AC13: =MANUAL!X13+OUTSALE!X13 -> 0 | AD13: =AB13-AC13 -> 3 | AF13: =O13+P13+U13+V13+W13+X13+Y13-Q13-R13-S13-T13 -> 120065.25
A14: =A13+1 -> 46304 | B14: =92582+105796.74 -> 198378.74 | C14: =750+195+169.8+222.5 -> 1337.3 | D14: =+B14-C14 -> 197041.44 | E14: 1337.3 | F14: =+C14-E14 -> 0 | H14: =42+39 -> 81 | I14: =SUMIF(AB14,"<.01") -> 0 | J14: =SUMIF(AB14,">.01") -> 1.81 | K14: 1 | L14: 6 | M14: 531 | O14: =70675+98455.25 -> 169130.25 | Z14: =20963+6950 -> 27913 | AA14: =D14-O14-P14+Q14+S14+T14-U14-V14-W14-X14-Y14 -> 27911.19 | AB14: =Z14-AA14 -> 1.81 | AC14: =MANUAL!X14+OUTSALE!X14 -> 0 | AD14: =AB14-AC14 -> 1.81 | AF14: =O14+P14+U14+V14+W14+X14+Y14-Q14-R14-S14-T14 -> 169130.25
A15: =A14+1 -> 46305 | B15: =132154.54+184082.5 -> 316237.04 | C15: =124+599.25+169.11+169.8+2399+349.5+155.45 -> 3966.11 | D15: =+B15-C15 -> 312270.93 | E15: 3966.11 | F15: =+C15-E15 -> 0 | H15: =63+79 -> 142 | I15: =SUMIF(AB15,"<.01") -> 0 | J15: =SUMIF(AB15,">.01") -> 5.3 | K15: 5 | L15: 4 | M15: 887 | O15: =96791.23+3400.75+145931.75 -> 246123.73 | X15: =10849+1326.5+2395 -> 14570.5 | Z15: =18900+32682 -> 51582 | AA15: =D15-O15-P15+Q15+S15+T15-U15-V15-W15-X15-Y15 -> 51576.7 | AB15: =Z15-AA15 -> 5.3 | AC15: =MANUAL!X15+OUTSALE!X15 -> 0 | AD15: =AB15-AC15 -> 5.3 | AF15: =O15+P15+U15+V15+W15+X15+Y15-Q15-R15-S15-T15 -> 260694.23
A16: =A15+1 -> 46306 | B16: =108316.15+207018.25 -> 315334.4 | C16: =169.8+235+136+2748.75 -> 3289.55 | D16: =+B16-C16 -> 312044.85 | E16: 3289.55 | F16: =+C16-E16 -> 0 | H16: =46+87 -> 133 | I16: =SUMIF(AB16,"<.01") -> 0 | J16: =SUMIF(AB16,">.01") -> 11.85 | M16: 595 | O16: =82777.7+180376.5 -> 263154.2 | T16: =2395+10849+1326.5 -> 14570.5 | Z16: =21559+41914 -> 63473 | AA16: =D16-O16-P16+Q16+S16+T16-U16-V16-W16-X16-Y16 -> 63461.15 | AB16: =Z16-AA16 -> 11.85 | AC16: =MANUAL!X16+OUTSALE!X16 -> 0 | AD16: =AB16-AC16 -> 11.85 | AF16: =O16+P16+U16+V16+W16+X16+Y16-Q16-R16-S16-T16 -> 248583.7
A17: =A16+1 -> 46307 | B17: =70048+500+87562 -> 158110 | C17: =169.8+139+349.5 -> 658.3 | D17: =+B17-C17 -> 157451.7 | F17: =+C17-E17 -> 658.3 | H17: =24 -> 24 | I17: =SUMIF(AB17,"<.01") -> 0 | J17: =SUMIF(AB17,">.01") -> 2 | K17: 0 | L17: 2 | M17: 336 | O17: =58744.7+60859 -> 119603.7 | X17: =939.5+500 -> 1439.5 | Z17: =10555.5+25855 -> 36410.5 | AA17: =D17-O17-P17+Q17+S17+T17-U17-V17-W17-X17-Y17 -> 36408.5 | AB17: =Z17-AA17 -> 2 | AC17: =MANUAL!X17+OUTSALE!X17 -> 0 | AD17: =AB17-AC17 -> 2 | AF17: =O17+P17+U17+V17+W17+X17+Y17-Q17-R17-S17-T17 -> 121043.2
A18: =A17+1 -> 46308 | D18: =+B18-C18 -> 0 | F18: =+C18-E18 -> 0 | I18: =SUMIF(AB18,"<.01") -> 0 | J18: =SUMIF(AB18,">.01") -> 0 | AA18: =D18-O18-P18+Q18+S18+T18-U18-V18-W18-X18-Y18 -> 0 | AB18: =Z18-AA18 -> 0 | AC18: =MANUAL!X18+OUTSALE!X18 -> 0 | AD18: =AB18-AC18 -> 0 | AF18: =O18+P18+U18+V18+W18+X18+Y18-Q18-R18-S18-T18 -> 0
A19: =A18+1 -> 46309 | D19: =+B19-C19 -> 0 | F19: =+C19-E19 -> 0 | I19: =SUMIF(AB19,"<.01") -> 0 | J19: =SUMIF(AB19,">.01") -> 0 | AA19: =D19-O19-P19+Q19+S19+T19-U19-V19-W19-X19-Y19 -> 0 | AB19: =Z19-AA19 -> 0 | AC19: =MANUAL!X19+OUTSALE!X19 -> 0 | AD19: =AB19-AC19 -> 0 | AE19: dfx | AF19: =O19+P19+U19+V19+W19+X19+Y19-Q19-R19-S19-T19 -> 0
A20: =A19+1 -> 46310 | D20: =+B20-C20 -> 0 | F20: =+C20-E20 -> 0 | I20: =SUMIF(AB20,"<.01") -> 0 | J20: =SUMIF(AB20,">.01") -> 0 | AA20: =D20-O20-P20+Q20+S20+T20-U20-V20-W20-X20-Y20 -> 0 | AB20: =Z20-AA20 -> 0 | AC20: =MANUAL!X20+OUTSALE!X20 -> 0 | AD20: =AB20-AC20 -> 0 | AF20: =O20+P20+U20+V20+W20+X20+Y20-Q20-R20-S20-T20 -> 0
A21: Subtotal | B21: =SUM(B6:B20) -> 2655900.6 | C21: =SUM(C6:C20) -> 16469.88 | D21: =+B21-C21 -> 2639430.7 | E21: =SUM(E6:E20) -> 15811.58 | F21: =SUM(F6:F20) -> 658.3 | G21: =SUM(G6:G20) -> 0 | H21: =SUM(H6:H20) -> 1013 | I21: =SUM(I6:I20) -> -47.2 | J21: =SUM(J6:J20) -> 41.75 | K21: =SUM(K6:K20) -> 16 | L21: =SUM(L6:L20) -> 38 | M21: =SUM(M6:M20) -> 6827 | O21: =SUM(O6:O20) -> 2150280.5 | P21: =SUM(P6:P20) -> 0 | Q21: =SUM(Q6:Q20) -> 3100 | R21: =SUM(R6:R20) -> 0 | S21: =SUM(S6:S20) -> 0 | T21: =SUM(T6:T20) -> 30566.5 | U21: =SUM(U6:U20) -> 0 | V21: =SUM(V6:V20) -> 400 | ... AD21: =SUM(AD6:AD20) -> -5.45
A23: =A20+1 -> 46311 | D23: =+B23-C23 -> 0 | F23: =+C23-E23 -> 0 | I23: =SUMIF(AB23,"<.01") -> 0 | J23: =SUMIF(AB23,">.01") -> 0 | AA23: =D23-O23-P23+Q23+S23+T23-U23-V23-W23-X23-Y23 -> 0 | AB23: =Z23-AA23 -> 0 | AC23: =MANUAL!X23+OUTSALE!X23 -> 0 | AD23: =AB23-AC23 -> 0 | AF23: =O23+P23+U23+V23+W23+X23+Y23-Q23-R23-S23-T23 -> 0
A24: =A23+1 -> 46312 | D24: =+B24-C24 -> 0 | F24: =+C24-E24 -> 0 | I24: =SUMIF(AB24,"<.01") -> 0 | J24: =SUMIF(AB24,">.01") -> 0 | AA24: =D24-O24-P24+Q24+S24+T24-U24-V24-W24-X24-Y24 -> 0 | AB24: =Z24-AA24 -> 0 | AC24: =MANUAL!X24+OUTSALE!X24 -> 0 | AD24: =AB24-AC24 -> 0 | AF24: =O24+P24+U24+V24+W24+X24+Y24-Q24-R24-S24-T24 -> 0
A25: =A24+1 -> 46313 | D25: =+B25-C25 -> 0 | F25: =+C25-E25 -> 0 | I25: 0 | J25: =SUMIF(AB25,">.01") -> 0 | AA25: =D25-O25-P25+Q25+S25+T25-U25-V25-W25-X25-Y25 -> 0 | AB25: =Z25-AA25 -> 0 | AC25: =MANUAL!X25+OUTSALE!X25 -> 0 | AD25: =AB25-AC25 -> 0 | AF25: =O25+P25+U25+V25+W25+X25+Y25-Q25-R25-S25-T25 -> 0
A26: =A25+1 -> 46314 | D26: =+B26-C26 -> 0 | F26: =+C26-E26 -> 0 | I26: =SUMIF(AB26,"<.01") -> 0 | J26: =SUMIF(AB26,">.01") -> 0 | AA26: =D26-O26-P26+Q26+S26+T26-U26-V26-W26-X26-Y26 -> 0 | AB26: =Z26-AA26 -> 0 | AC26: =MANUAL!X26+OUTSALE!X26 -> 0 | AD26: =AB26-AC26 -> 0 | AF26: =O26+P26+U26+V26+W26+X26+Y26-Q26-R26-S26-T26 -> 0
A27: =A26+1 -> 46315 | D27: =+B27-C27 -> 0 | F27: =+C27-E27 -> 0 | I27: =SUMIF(AB27,"<.01") -> 0 | J27: =SUMIF(AB27,">.01") -> 0 | AA27: =D27-O27-P27+Q27+S27+T27-U27-V27-W27-X27-Y27 -> 0 | AB27: =Z27-AA27 -> 0 | AC27: =MANUAL!X27+OUTSALE!X27 -> 0 | AD27: =AB27-AC27 -> 0 | AF27: =O27+P27+U27+V27+W27+X27+Y27-Q27-R27-S27-T27 -> 0
A28: =A27+1 -> 46316 | D28: =+B28-C28 -> 0 | F28: =+C28-E28 -> 0 | I28: =SUMIF(AB28,"<.01") -> 0 | J28: =SUMIF(AB28,">.01") -> 0 | AA28: =D28-O28-P28+Q28+S28+T28-U28-V28-W28-X28-Y28 -> 0 | AB28: =Z28-AA28 -> 0 | AC28: =MANUAL!X28+OUTSALE!X28 -> 0 | AD28: =AB28-AC28 -> 0 | AF28: =O28+P28+U28+V28+W28+X28+Y28-Q28-R28-S28-T28 -> 0
A29: =A28+1 -> 46317 | D29: =+B29-C29 -> 0 | F29: =+C29-E29 -> 0 | I29: =SUMIF(AB29,"<.01") -> 0 | J29: =SUMIF(AB29,">.01") -> 0 | AA29: =D29-O29-P29+Q29+S29+T29-U29-V29-W29-X29-Y29 -> 0 | AB29: =Z29-AA29 -> 0 | AC29: =MANUAL!X29+OUTSALE!X29 -> 0 | AD29: =AB29-AC29 -> 0 | AF29: =O29+P29+U29+V29+W29+X29+Y29-Q29-R29-S29-T29 -> 0
A30: =A29+1 -> 46318 | D30: =+B30-C30 -> 0 | F30: =+C30-E30 -> 0 | I30: =SUMIF(AB30,"<.01") -> 0 | J30: =SUMIF(AB30,">.01") -> 0 | AA30: =D30-O30-P30+Q30+S30+T30-U30-V30-W30-X30-Y30 -> 0 | AB30: =Z30-AA30 -> 0 | AC30: =MANUAL!X30+OUTSALE!X30 -> 0 | AD30: =AB30-AC30 -> 0 | AF30: =O30+P30+U30+V30+W30+X30+Y30-Q30-R30-S30-T30 -> 0
A31: =A30+1 -> 46319 | D31: =+B31-C31 -> 0 | F31: =+C31-E31 -> 0 | I31: =SUMIF(AB31,"<.01") -> 0 | J31: =SUMIF(AB31,">.01") -> 0 | AA31: =D31-O31-P31+Q31+S31+T31-U31-V31-W31-X31-Y31 -> 0 | AB31: =Z31-AA31 -> 0 | AC31: =MANUAL!X31+OUTSALE!X31 -> 0 | AD31: =AB31-AC31 -> 0 | AF31: =O31+P31+U31+V31+W31+X31+Y31-Q31-R31-S31-T31 -> 0
A32: =A31+1 -> 46320 | D32: =+B32-C32 -> 0 | F32: =+C32-E32 -> 0 | I32: =SUMIF(AB32,"<.01") -> 0 | J32: =SUMIF(AB32,">.01") -> 0 | AA32: =D32-O32-P32+Q32+S32+T32-U32-V32-W32-X32-Y32 -> 0 | AB32: =Z32-AA32 -> 0 | AC32: =MANUAL!X32+OUTSALE!X32 -> 0 | AD32: =AB32-AC32 -> 0 | AF32: =O32+P32+U32+V32+W32+X32+Y32-Q32-R32-S32-T32 -> 0
A33: =A32+1 -> 46321 | D33: =+B33-C33 -> 0 | F33: =+C33-E33 -> 0 | I33: =SUMIF(AB33,"<.01") -> 0 | J33: =SUMIF(AB33,">.01") -> 0 | AA33: =D33-O33-P33+Q33+S33+T33-U33-V33-W33-X33-Y33 -> 0 | AB33: =Z33-AA33 -> 0 | AC33: =MANUAL!X33+OUTSALE!X33 -> 0 | AD33: =AB33-AC33 -> 0 | AF33: =O33+P33+U33+V33+W33+X33+Y33-Q33-R33-S33-T33 -> 0
A34: =A33+1 -> 46322 | D34: =+B34-C34 -> 0 | F34: =+C34-E34 -> 0 | I34: =SUMIF(AB34,"<.01") -> 0 | J34: =SUMIF(AB34,">.01") -> 0 | AA34: =D34-O34-P34+Q34+S34+T34-U34-V34-W34-X34-Y34 -> 0 | AB34: =Z34-AA34 -> 0 | AC34: =MANUAL!X34+OUTSALE!X34 -> 0 | AD34: =AB34-AC34 -> 0 | AF34: =O34+P34+U34+V34+W34+X34+Y34-Q34-R34-S34-T34 -> 0
A35: =A34+1 -> 46323 | D35: =+B35-C35 -> 0 | F35: =+C35-E35 -> 0 | I35: =SUMIF(AB35,"<.01") -> 0 | J35: =SUMIF(AB35,">.01") -> 0 | AA35: =D35-O35-P35+Q35+S35+T35-U35-V35-W35-X35-Y35 -> 0 | AB35: =Z35-AA35 -> 0 | AC35: =MANUAL!X35+OUTSALE!X35 -> 0 | AD35: =AB35-AC35 -> 0 | AF35: =O35+P35+U35+V35+W35+X35+Y35-Q35-R35-S35-T35 -> 0
A36: =A35+1 -> 46324 | D36: =+B36-C36 -> 0 | F36: =+C36-E36 -> 0 | I36: =SUMIF(AB36,"<.01") -> 0 | J36: =SUMIF(AB36,">.01") -> 0 | AA36: =D36-O36-P36+Q36+S36+T36-U36-V36-W36-X36-Y36 -> 0 | AB36: =Z36-AA36 -> 0 | AC36: =MANUAL!X36+OUTSALE!X36 -> 0 | AD36: =AB36-AC36 -> 0 | AF36: =O36+P36+U36+V36+W36+X36+Y36-Q36-R36-S36-T36 -> 0
A37: =A36+1 -> 46325 | D37: =+B37-C37 -> 0 | F37: =+C37-E37 -> 0 | I37: =SUMIF(AB37,"<.01") -> 0 | J37: =SUMIF(AB37,">.01") -> 0 | AA37: =D37-O37-P37+Q37+S37+T37-U37-V37-W37-X37-Y37 -> 0 | AB37: =Z37-AA37 -> 0 | AC37: =MANUAL!X37+OUTSALE!X37 -> 0 | AD37: =AB37-AC37 -> 0 | AF37: =O37+P37+U37+V37+W37+X37+Y37-Q37-R37-S37-T37 -> 0
A38: =A37+1 -> 46326 | D38: =+B38-C38 -> 0 | F38: =+C38-E38 -> 0 | I38: =SUMIF(AB38,"<.01") -> 0 | J38: =SUMIF(AB38,">.01") -> 0 | AA38: =D38-O38-P38+Q38+S38+T38-U38-V38-W38-X38-Y38 -> 0 | AB38: =Z38-AA38 -> 0 | AC38: =MANUAL!X38+OUTSALE!X38 -> 0 | AD38: =AB38-AC38 -> 0 | AF38: =O38+P38+U38+V38+W38+X38+Y38-Q38-R38-S38-T38 -> 0
A39: Subtotal | B39: =SUM(B23:B38) -> 0 | C39: =SUM(C23:C38) -> 0 | D39: =SUM(D23:D38) -> 0 | E39: =SUM(E23:E38) -> 0 | F39: =SUM(F23:F38) -> 0 | G39: =SUM(G23:G38) -> 0 | H39: =SUM(H23:H38) -> 0 | I39: =SUM(I23:I38) -> 0 | ... M39: =SUM(M23:M38) -> 0 | O39: =SUM(O23:O38) -> 0 | P39: =SUM(P23:P38) -> 0 | Q39: =SUM(Q23:Q38) -> 0 | R39: =SUM(R23:R38) -> 0 | S39: =SUM(S23:S38) -> 0 | T39: =SUM(T23:T38) -> 0 | U39: =SUM(U23:U38) -> 0 | V39: =SUM(V23:V38) -> 0 | ... AD39: =SUM(AD23:AD38) -> 0
A41: Total | B41: =+B21+B39 -> 2655900.6 | C41: =+C21+C39 -> 16469.88 | D41: =+B41-C41 -> 2639430.7 | E41: =+E21+E39 -> 15811.58 | F41: =+C41-E41 -> 658.3 | G41: =+G21+G39 -> 0 | H41: =+H21+H39 -> 1013 | I41: =+I21+I39 -> -47.2 | J41: =+J21+J39 -> 41.75 | K41: =+K21+K39 -> 16 | L41: =+L21+L39 -> 38 | M41: =+M21+M39 -> 6827 | O41: =+O21+O39 -> 2150280.5 | P41: =+P21+P39 -> 0 | Q41: =+Q21+Q39 -> 3100 | R41: =+R21+R39 -> 0 | S41: =+S21+S39 -> 0 | T41: =+T21+T39 -> 30566.5 | U41: =+U21+U39 -> 0 | V41: =+V21+V39 -> 400 | ... AD41: =+AD21+AD39 -> -5.45

Sheet MSI
A1: MANUALLY ADDED TRANSACTIONS
A2: DATE: APRIL 1-30, 2025
A3: Store Code:
A4: LEGEND: | B4: REASON(LS-POP UP)
A5: INF- | B5: ITEM NOT ON FILE
A6: WP- | B6: WRONG PRICE
P7: DISCOUNT | V7: CHARGE
A8: BRANCH | B8: DATE | C8: CSI No. | D8: Manual /OutSale | E8: SALES ORDER # | F8: Sales Shipment No. | G8: CON/ OUT | H8: ALU/UPC | I8: BRAND | J8: DESCRIPTION1 | K8: DESC2/ ARTICLE # | L8: SIZE/ COLOR | M8: QTY | N8: Unit Price | O8: SP | P8: % | Q8: DISC. AMOUNT | R8: NET PRICE | S8: CASH | T8: Check | U8: COD | V8: CREDIT CARD | W8: EMPLOYEES' CHARGE | X8: Other Charge | Y8: Customer Name for Charge transaction | Z8: CHARGE | AA8: GC/ OTHERS | AB8: CWT | AC8: REASON(LS-POP UP) | AD8: REMARKS | AE8: CASHIER NAME | AF8: SALES PERSON(SA) SALES AGENT | AG8: MIS-REMARKS
O9: =M9*N9 -> 0 | Q9: =O9*P9 -> 0 | R9: =O9-Q9 -> 0
O10: =M10*N10 -> 0 | Q10: =O10*P10 -> 0 | R10: =O10-Q10 -> 0
O11: =M11*N11 -> 0 | Q11: =O11*P11 -> 0 | R11: =O11-Q11 -> 0
O12: =M12*N12 -> 0 | Q12: =O12*P12 -> 0 | R12: =O12-Q12 -> 0
O13: =M13*N13 -> 0 | Q13: =O13*P13 -> 0 | R13: =O13-Q13 -> 0
O14: =M14*N14 -> 0 | Q14: =O14*P14 -> 0 | R14: =O14-Q14 -> 0
O15: =M15*N15 -> 0 | Q15: =O15*P15 -> 0 | R15: =O15-Q15 -> 0
O16: =M16*N16 -> 0 | Q16: =O16*P16 -> 0 | R16: =O16-Q16 -> 0
O17: =M17*N17 -> 0 | Q17: =O17*P17 -> 0 | R17: =O17-Q17 -> 0
O18: =M18*N18 -> 0 | Q18: =O18*P18 -> 0 | R18: =O18-Q18 -> 0
O19: =M19*N19 -> 0 | Q19: =O19*P19 -> 0 | R19: =O19-Q19 -> 0
O303: =SUBTOTAL(9,O10:O302) -> 0

Sheet MRet
A1: MANUAL RETURNS
A2: DATE: APRIL 1-30, 2025
A3: Store Code: | B3: =MSI!B3 -> 0
A4: LEGEND: | B4: REASON(LS-POP UP)
A5: INF- | B5: ITEM NOT ON FILE
A6: WP- | B6: WRONG PRICE
P7: DISCOUNT | V7: CHARGE
A8: BRANCH | B8: DATE | C8: RS# | D8: Manual/ OutSale | E8: SALES ORDER # | F8: Return Receipt No. | G8: CON/ OUT | H8: ALU/UPC | I8: BRAND | J8: DESCRIPTION1 | K8: DESC2/ARTICLE # | L8: SIZE/COLOR | M8: QTY | N8: Unit Price | O8: SP | P8: % | Q8: DISC. AMOUNT | R8: NET PRICE | S8: CASH | T8: Check | U8: COD | V8: CREDIT CARD | W8: EMPLOYEES' CHARGE | X8: Other Charge | Y8: Customer Name for Charge transaction | Z8: CHARGE | AA8: GC/ OTHERS | AB8: CWT | AC8: REASON(LS-POP UP) | AD8: REMARKS | AE8: CASHIER NAME | AF8: SALES PERSON(SA) SALES AGENT | AG8: MIS-REMARKS
A9: =B$3 -> 0 | O9: =M9*N9 -> 0 | Q9: =O9*P9 -> 0 | R9: =O9-Q9 -> 0 | Z9: =MRet[[#This Row],[CREDIT CARD]]+MRet[[#This Row],[EMPLOYEES'' CHARGE]]+MRet[[#This Row],[Other Charge]] -> 0
A10: =B$3 -> 0 | O10: =M10*N10 -> 0 | Q10: =O10*P10 -> 0 | R10: =O10-Q10 -> 0 | Z10: =MRet[[#This Row],[CREDIT CARD]]+MRet[[#This Row],[EMPLOYEES'' CHARGE]]+MRet[[#This Row],[Other Charge]] -> 0
A11: =B$3 -> 0 | O11: =M11*N11 -> 0 | Q11: =O11*P11 -> 0 | R11: =O11-Q11 -> 0 | Z11: =MRet[[#This Row],[CREDIT CARD]]+MRet[[#This Row],[EMPLOYEES'' CHARGE]]+MRet[[#This Row],[Other Charge]] -> 0
A12: =B$3 -> 0 | O12: =M12*N12 -> 0 | Q12: =O12*P12 -> 0 | R12: =O12-Q12 -> 0 | Z12: =MRet[[#This Row],[CREDIT CARD]]+MRet[[#This Row],[EMPLOYEES'' CHARGE]]+MRet[[#This Row],[Other Charge]] -> 0
A13: =B$3 -> 0 | O13: =M13*N13 -> 0 | Q13: =O13*P13 -> 0 | R13: =O13-Q13 -> 0 | Z13: =MRet[[#This Row],[CREDIT CARD]]+MRet[[#This Row],[EMPLOYEES'' CHARGE]]+MRet[[#This Row],[Other Charge]] -> 0
A14: =B$3 -> 0 | O14: =M14*N14 -> 0 | Q14: =O14*P14 -> 0 | R14: =O14-Q14 -> 0 | Z14: =MRet[[#This Row],[CREDIT CARD]]+MRet[[#This Row],[EMPLOYEES'' CHARGE]]+MRet[[#This Row],[Other Charge]] -> 0
A15: =B$3 -> 0 | O15: =M15*N15 -> 0 | Q15: =O15*P15 -> 0 | R15: =O15-Q15 -> 0 | Z15: =MRet[[#This Row],[CREDIT CARD]]+MRet[[#This Row],[EMPLOYEES'' CHARGE]]+MRet[[#This Row],[Other Charge]] -> 0
A16: =B$3 -> 0 | O16: =M16*N16 -> 0 | Q16: =O16*P16 -> 0 | R16: =O16-Q16 -> 0 | Z16: =MRet[[#This Row],[CREDIT CARD]]+MRet[[#This Row],[EMPLOYEES'' CHARGE]]+MRet[[#This Row],[Other Charge]] -> 0
O330: =SUBTOTAL(9,O10:O329) -> 0

Sheet MANUAL
A1: MANUAL
A2: =LS_RPRO!A2 -> 46296
E4: Details of Discount | H4: NO. | M4: CHARGE | N4: GIFT | O4: OTHER COLLECTION | S4: CHECKS | T4: OTHER DISBURSEMENT | X4: CASH | Y4: CASH SALES | Z4: Over/(short)
B5: GROSS | C5: DISCOUNT | D5: NET SALES | E5: ÀPPROVED DISC | F5: DISC W/O APPROVAL | G5: DEL. FEE | H5: CUSTOMER | I5: SHORTAGE | J5: OVERAGE | K5: INVOICES | M5: SALES | N5: CHECK | O5: GC ISSUED-cash | P5: GC ISSUED-card | Q5: DOWNPAYMENT | R5: ADV | T5: COD | U5: CASH ADVANCE | V5: (ADV) | W5: CWT | Y5: AVAILABLE
A6: =A2+0 -> 46296 | B6: =(SUMIFS(msi[[#All],[SP]],msi[[#All],[DATE]],$A6,msi[[#All],[Manual /OutSale]],"Manual"))-(SUMIFS(MRet[[#All],[SP]],MRet[[#All],[DATE]],$A6,MRet[[#All],[Manual/ OutSale]],"Manual")) -> 0 | C6: =(SUMIFS(msi[[#All],[DISC. AMOUNT]],msi[[#All],[DATE]],$A6,msi[[#All],[Manual /OutSale]],"Manual"))-(SUMIFS(MRet[[#All],[DISC. AMOUNT]],MRet[[#All],[DATE]],$A6,MRet[[#All],[Manual/ OutSale]],"Manual")) -> 0 | D6: =+B6-C6 -> 0 | F6: =+C6-E6 -> 0 | I6: =SUMIF(Z6,"<.01") -> 0 | J6: =SUMIF(Z6,">.01") -> 0 | M6: =(SUMIFS(msi[[#All],[CHARGE]],msi[[#All],[DATE]],$A6,msi[[#All],[Manual /OutSale]],"Manual"))-(SUMIFS(MRet[[#All],[CHARGE]],MRet[[#All],[DATE]],$A6,MRet[[#All],[Manual/ OutSale]],"Manual")) -> 0 | N6: =(SUMIFS(msi[[#All],[GC/ OTHERS]],msi[[#All],[DATE]],$A6,msi[[#All],[Manual /OutSale]],"Manual"))-(SUMIFS(MRet[[#All],[GC/ OTHERS]],MRet[[#All],[DATE]],$A6,MRet[[#All],[Manual/ OutSale]],"Manual")) -> 0 | S6: =(SUMIFS(msi[[#All],[Check]],msi[[#All],[DATE]],$A6,msi[[#All],[Manual /OutSale]],"Manual"))-(SUMIFS(MRet[[#All],[Check]],MRet[[#All],[DATE]],$A6,MRet[[#All],[Manual/ OutSale]],"Manual")) -> 0 | T6: =(SUMIFS(msi[[#All],[COD]],msi[[#All],[DATE]],$A6,msi[[#All],[Manual /OutSale]],"Manual"))-(SUMIFS(MRet[[#All],[COD]],MRet[[#All],[DATE]],$A6,MRet[[#All],[Manual/ OutSale]],"Manual")) -> 0 | U6: 0 | W6: =(SUMIFS(msi[[#All],[CWT]],msi[[#All],[DATE]],$A6,msi[[#All],[Manual /OutSale]],"Manual"))-(SUMIFS(MRet[[#All],[CWT]],MRet[[#All],[DATE]],$A6,MRet[[#All],[Manual/ OutSale]],"Manual")) -> 0 | X6: =(SUMIFS(msi[[#All],[CASH]],msi[[#All],[DATE]],$A6,msi[[#All],[Manual /OutSale]],"Manual"))-(SUMIFS(MRet[[#All],[CASH]],MRet[[#All],[DATE]],$A6,MRet[[#All],[Manual/ OutSale]],"Manual")) -> 0 | Y6: =D6-M6-N6+O6+Q6+R6-S6-T6-U6-V6-W6 -> 0 | Z6: =X6-Y6 -> 0
A7: =A6+1 -> 46297 | B7: =(SUMIFS(msi[[#All],[SP]],msi[[#All],[DATE]],$A7,msi[[#All],[Manual /OutSale]],"Manual"))-(SUMIFS(MRet[[#All],[SP]],MRet[[#All],[DATE]],$A7,MRet[[#All],[Manual/ OutSale]],"Manual")) -> 0 | C7: =(SUMIFS(msi[[#All],[DISC. AMOUNT]],msi[[#All],[DATE]],$A7,msi[[#All],[Manual /OutSale]],"Manual"))-(SUMIFS(MRet[[#All],[DISC. AMOUNT]],MRet[[#All],[DATE]],$A7,MRet[[#All],[Manual/ OutSale]],"Manual")) -> 0 | D7: =+B7-C7 -> 0 | F7: =+C7-E7 -> 0 | I7: =SUMIF(Z7,"<.01") -> 0 | J7: =SUMIF(Z7,">.01") -> 0 | M7: =(SUMIFS(msi[[#All],[CHARGE]],msi[[#All],[DATE]],$A7,msi[[#All],[Manual /OutSale]],"Manual"))-(SUMIFS(MRet[[#All],[CHARGE]],MRet[[#All],[DATE]],$A7,MRet[[#All],[Manual/ OutSale]],"Manual")) -> 0 | N7: =(SUMIFS(msi[[#All],[GC/ OTHERS]],msi[[#All],[DATE]],$A7,msi[[#All],[Manual /OutSale]],"Manual"))-(SUMIFS(MRet[[#All],[GC/ OTHERS]],MRet[[#All],[DATE]],$A7,MRet[[#All],[Manual/ OutSale]],"Manual")) -> 0 | S7: =(SUMIFS(msi[[#All],[Check]],msi[[#All],[DATE]],$A7,msi[[#All],[Manual /OutSale]],"Manual"))-(SUMIFS(MRet[[#All],[Check]],MRet[[#All],[DATE]],$A7,MRet[[#All],[Manual/ OutSale]],"Manual")) -> 0 | T7: =(SUMIFS(msi[[#All],[COD]],msi[[#All],[DATE]],$A7,msi[[#All],[Manual /OutSale]],"Manual"))-(SUMIFS(MRet[[#All],[COD]],MRet[[#All],[DATE]],$A7,MRet[[#All],[Manual/ OutSale]],"Manual")) -> 0 | U7: 0 | W7: =(SUMIFS(msi[[#All],[CWT]],msi[[#All],[DATE]],$A7,msi[[#All],[Manual /OutSale]],"Manual"))-(SUMIFS(MRet[[#All],[CWT]],MRet[[#All],[DATE]],$A7,MRet[[#All],[Manual/ OutSale]],"Manual")) -> 0 | X7: =(SUMIFS(msi[[#All],[CASH]],msi[[#All],[DATE]],$A7,msi[[#All],[Manual /OutSale]],"Manual"))-(SUMIFS(MRet[[#All],[CASH]],MRet[[#All],[DATE]],$A7,MRet[[#All],[Manual/ OutSale]],"Manual")) -> 0 | Y7: =D7-M7-N7+O7+Q7+R7-S7-T7-U7-V7-W7 -> 0 | Z7: =X7-Y7 -> 0
A8: =A7+1 -> 46298 | B8: =(SUMIFS(msi[[#All],[SP]],msi[[#All],[DATE]],$A8,msi[[#All],[Manual /OutSale]],"Manual"))-(SUMIFS(MRet[[#All],[SP]],MRet[[#All],[DATE]],$A8,MRet[[#All],[Manual/ OutSale]],"Manual")) -> 0 | C8: =(SUMIFS(msi[[#All],[DISC. AMOUNT]],msi[[#All],[DATE]],$A8,msi[[#All],[Manual /OutSale]],"Manual"))-(SUMIFS(MRet[[#All],[DISC. AMOUNT]],MRet[[#All],[DATE]],$A8,MRet[[#All],[Manual/ OutSale]],"Manual")) -> 0 | D8: =+B8-C8 -> 0 | F8: =+C8-E8 -> 0 | I8: =SUMIF(Z8,"<.01") -> 0 | J8: =SUMIF(Z8,">.01") -> 0 | M8: =(SUMIFS(msi[[#All],[CHARGE]],msi[[#All],[DATE]],$A8,msi[[#All],[Manual /OutSale]],"Manual"))-(SUMIFS(MRet[[#All],[CHARGE]],MRet[[#All],[DATE]],$A8,MRet[[#All],[Manual/ OutSale]],"Manual")) -> 0 | N8: =(SUMIFS(msi[[#All],[GC/ OTHERS]],msi[[#All],[DATE]],$A8,msi[[#All],[Manual /OutSale]],"Manual"))-(SUMIFS(MRet[[#All],[GC/ OTHERS]],MRet[[#All],[DATE]],$A8,MRet[[#All],[Manual/ OutSale]],"Manual")) -> 0 | S8: =(SUMIFS(msi[[#All],[Check]],msi[[#All],[DATE]],$A8,msi[[#All],[Manual /OutSale]],"Manual"))-(SUMIFS(MRet[[#All],[Check]],MRet[[#All],[DATE]],$A8,MRet[[#All],[Manual/ OutSale]],"Manual")) -> 0 | T8: =(SUMIFS(msi[[#All],[COD]],msi[[#All],[DATE]],$A8,msi[[#All],[Manual /OutSale]],"Manual"))-(SUMIFS(MRet[[#All],[COD]],MRet[[#All],[DATE]],$A8,MRet[[#All],[Manual/ OutSale]],"Manual")) -> 0 | U8: 0 | W8: =(SUMIFS(msi[[#All],[CWT]],msi[[#All],[DATE]],$A8,msi[[#All],[Manual /OutSale]],"Manual"))-(SUMIFS(MRet[[#All],[CWT]],MRet[[#All],[DATE]],$A8,MRet[[#All],[Manual/ OutSale]],"Manual")) -> 0 | X8: =(SUMIFS(msi[[#All],[CASH]],msi[[#All],[DATE]],$A8,msi[[#All],[Manual /OutSale]],"Manual"))-(SUMIFS(MRet[[#All],[CASH]],MRet[[#All],[DATE]],$A8,MRet[[#All],[Manual/ OutSale]],"Manual")) -> 0 | Y8: =D8-M8-N8+O8+Q8+R8-S8-T8-U8-V8-W8 -> 0 | Z8: =X8-Y8 -> 0
A9: =A8+1 -> 46299 | B9: =(SUMIFS(msi[[#All],[SP]],msi[[#All],[DATE]],$A9,msi[[#All],[Manual /OutSale]],"Manual"))-(SUMIFS(MRet[[#All],[SP]],MRet[[#All],[DATE]],$A9,MRet[[#All],[Manual/ OutSale]],"Manual")) -> 0 | C9: =(SUMIFS(msi[[#All],[DISC. AMOUNT]],msi[[#All],[DATE]],$A9,msi[[#All],[Manual /OutSale]],"Manual"))-(SUMIFS(MRet[[#All],[DISC. AMOUNT]],MRet[[#All],[DATE]],$A9,MRet[[#All],[Manual/ OutSale]],"Manual")) -> 0 | D9: =+B9-C9 -> 0 | F9: =+C9-E9 -> 0 | I9: =SUMIF(Z9,"<.01") -> 0 | J9: =SUMIF(Z9,">.01") -> 0 | M9: =(SUMIFS(msi[[#All],[CHARGE]],msi[[#All],[DATE]],$A9,msi[[#All],[Manual /OutSale]],"Manual"))-(SUMIFS(MRet[[#All],[CHARGE]],MRet[[#All],[DATE]],$A9,MRet[[#All],[Manual/ OutSale]],"Manual")) -> 0 | N9: =(SUMIFS(msi[[#All],[GC/ OTHERS]],msi[[#All],[DATE]],$A9,msi[[#All],[Manual /OutSale]],"Manual"))-(SUMIFS(MRet[[#All],[GC/ OTHERS]],MRet[[#All],[DATE]],$A9,MRet[[#All],[Manual/ OutSale]],"Manual")) -> 0 | S9: =(SUMIFS(msi[[#All],[Check]],msi[[#All],[DATE]],$A9,msi[[#All],[Manual /OutSale]],"Manual"))-(SUMIFS(MRet[[#All],[Check]],MRet[[#All],[DATE]],$A9,MRet[[#All],[Manual/ OutSale]],"Manual")) -> 0 | T9: =(SUMIFS(msi[[#All],[COD]],msi[[#All],[DATE]],$A9,msi[[#All],[Manual /OutSale]],"Manual"))-(SUMIFS(MRet[[#All],[COD]],MRet[[#All],[DATE]],$A9,MRet[[#All],[Manual/ OutSale]],"Manual")) -> 0 | U9: 0 | W9: =(SUMIFS(msi[[#All],[CWT]],msi[[#All],[DATE]],$A9,msi[[#All],[Manual /OutSale]],"Manual"))-(SUMIFS(MRet[[#All],[CWT]],MRet[[#All],[DATE]],$A9,MRet[[#All],[Manual/ OutSale]],"Manual")) -> 0 | X9: =(SUMIFS(msi[[#All],[CASH]],msi[[#All],[DATE]],$A9,msi[[#All],[Manual /OutSale]],"Manual"))-(SUMIFS(MRet[[#All],[CASH]],MRet[[#All],[DATE]],$A9,MRet[[#All],[Manual/ OutSale]],"Manual")) -> 0 | Y9: =D9-M9-N9+O9+Q9+R9-S9-T9-U9-V9-W9 -> 0 | Z9: =X9-Y9 -> 0
A10: =A9+1 -> 46300 | B10: =(SUMIFS(msi[[#All],[SP]],msi[[#All],[DATE]],$A10,msi[[#All],[Manual /OutSale]],"Manual"))-(SUMIFS(MRet[[#All],[SP]],MRet[[#All],[DATE]],$A10,MRet[[#All],[Manual/ OutSale]],"Manual")) -> 0 | C10: =(SUMIFS(msi[[#All],[DISC. AMOUNT]],msi[[#All],[DATE]],$A10,msi[[#All],[Manual /OutSale]],"Manual"))-(SUMIFS(MRet[[#All],[DISC. AMOUNT]],MRet[[#All],[DATE]],$A10,MRet[[#All],[Manual/ OutSale]],"Manual")) -> 0 | D10: =+B10-C10 -> 0 | F10: =+C10-E10 -> 0 | I10: =SUMIF(Z10,"<.01") -> 0 | J10: =SUMIF(Z10,">.01") -> 0 | M10: =(SUMIFS(msi[[#All],[CHARGE]],msi[[#All],[DATE]],$A10,msi[[#All],[Manual /OutSale]],"Manual"))-(SUMIFS(MRet[[#All],[CHARGE]],MRet[[#All],[DATE]],$A10,MRet[[#All],[Manual/ OutSale]],"Manual")) -> 0 | N10: =(SUMIFS(msi[[#All],[GC/ OTHERS]],msi[[#All],[DATE]],$A10,msi[[#All],[Manual /OutSale]],"Manual"))-(SUMIFS(MRet[[#All],[GC/ OTHERS]],MRet[[#All],[DATE]],$A10,MRet[[#All],[Manual/ OutSale]],"Manual")) -> 0 | S10: =(SUMIFS(msi[[#All],[Check]],msi[[#All],[DATE]],$A10,msi[[#All],[Manual /OutSale]],"Manual"))-(SUMIFS(MRet[[#All],[Check]],MRet[[#All],[DATE]],$A10,MRet[[#All],[Manual/ OutSale]],"Manual")) -> 0 | T10: =(SUMIFS(msi[[#All],[COD]],msi[[#All],[DATE]],$A10,msi[[#All],[Manual /OutSale]],"Manual"))-(SUMIFS(MRet[[#All],[COD]],MRet[[#All],[DATE]],$A10,MRet[[#All],[Manual/ OutSale]],"Manual")) -> 0 | U10: 0 | W10: =(SUMIFS(msi[[#All],[CWT]],msi[[#All],[DATE]],$A10,msi[[#All],[Manual /OutSale]],"Manual"))-(SUMIFS(MRet[[#All],[CWT]],MRet[[#All],[DATE]],$A10,MRet[[#All],[Manual/ OutSale]],"Manual")) -> 0 | X10: =(SUMIFS(msi[[#All],[CASH]],msi[[#All],[DATE]],$A10,msi[[#All],[Manual /OutSale]],"Manual"))-(SUMIFS(MRet[[#All],[CASH]],MRet[[#All],[DATE]],$A10,MRet[[#All],[Manual/ OutSale]],"Manual")) -> 0 | Y10: =D10-M10-N10+O10+Q10+R10-S10-T10-U10-V10-W10 -> 0 | Z10: =X10-Y10 -> 0
A11: =A10+1 -> 46301 | B11: =(SUMIFS(msi[[#All],[SP]],msi[[#All],[DATE]],$A11,msi[[#All],[Manual /OutSale]],"Manual"))-(SUMIFS(MRet[[#All],[SP]],MRet[[#All],[DATE]],$A11,MRet[[#All],[Manual/ OutSale]],"Manual")) -> 0 | C11: =(SUMIFS(msi[[#All],[DISC. AMOUNT]],msi[[#All],[DATE]],$A11,msi[[#All],[Manual /OutSale]],"Manual"))-(SUMIFS(MRet[[#All],[DISC. AMOUNT]],MRet[[#All],[DATE]],$A11,MRet[[#All],[Manual/ OutSale]],"Manual")) -> 0 | D11: =+B11-C11 -> 0 | F11: =+C11-E11 -> 0 | I11: =SUMIF(Z11,"<.01") -> 0 | J11: =SUMIF(Z11,">.01") -> 0 | M11: =(SUMIFS(msi[[#All],[CHARGE]],msi[[#All],[DATE]],$A11,msi[[#All],[Manual /OutSale]],"Manual"))-(SUMIFS(MRet[[#All],[CHARGE]],MRet[[#All],[DATE]],$A11,MRet[[#All],[Manual/ OutSale]],"Manual")) -> 0 | N11: =(SUMIFS(msi[[#All],[GC/ OTHERS]],msi[[#All],[DATE]],$A11,msi[[#All],[Manual /OutSale]],"Manual"))-(SUMIFS(MRet[[#All],[GC/ OTHERS]],MRet[[#All],[DATE]],$A11,MRet[[#All],[Manual/ OutSale]],"Manual")) -> 0 | S11: =(SUMIFS(msi[[#All],[Check]],msi[[#All],[DATE]],$A11,msi[[#All],[Manual /OutSale]],"Manual"))-(SUMIFS(MRet[[#All],[Check]],MRet[[#All],[DATE]],$A11,MRet[[#All],[Manual/ OutSale]],"Manual")) -> 0 | T11: =(SUMIFS(msi[[#All],[COD]],msi[[#All],[DATE]],$A11,msi[[#All],[Manual /OutSale]],"Manual"))-(SUMIFS(MRet[[#All],[COD]],MRet[[#All],[DATE]],$A11,MRet[[#All],[Manual/ OutSale]],"Manual")) -> 0 | U11: 0 | W11: =(SUMIFS(msi[[#All],[CWT]],msi[[#All],[DATE]],$A11,msi[[#All],[Manual /OutSale]],"Manual"))-(SUMIFS(MRet[[#All],[CWT]],MRet[[#All],[DATE]],$A11,MRet[[#All],[Manual/ OutSale]],"Manual")) -> 0 | X11: =(SUMIFS(msi[[#All],[CASH]],msi[[#All],[DATE]],$A11,msi[[#All],[Manual /OutSale]],"Manual"))-(SUMIFS(MRet[[#All],[CASH]],MRet[[#All],[DATE]],$A11,MRet[[#All],[Manual/ OutSale]],"Manual")) -> 0 | Y11: =D11-M11-N11+O11+Q11+R11-S11-T11-U11-V11-W11 -> 0 | Z11: =X11-Y11 -> 0
A12: =A11+1 -> 46302 | B12: =(SUMIFS(msi[[#All],[SP]],msi[[#All],[DATE]],$A12,msi[[#All],[Manual /OutSale]],"Manual"))-(SUMIFS(MRet[[#All],[SP]],MRet[[#All],[DATE]],$A12,MRet[[#All],[Manual/ OutSale]],"Manual")) -> 0 | C12: =(SUMIFS(msi[[#All],[DISC. AMOUNT]],msi[[#All],[DATE]],$A12,msi[[#All],[Manual /OutSale]],"Manual"))-(SUMIFS(MRet[[#All],[DISC. AMOUNT]],MRet[[#All],[DATE]],$A12,MRet[[#All],[Manual/ OutSale]],"Manual")) -> 0 | D12: =+B12-C12 -> 0 | F12: =+C12-E12 -> 0 | I12: =SUMIF(Z12,"<.01") -> 0 | J12: =SUMIF(Z12,">.01") -> 0 | M12: =(SUMIFS(msi[[#All],[CHARGE]],msi[[#All],[DATE]],$A12,msi[[#All],[Manual /OutSale]],"Manual"))-(SUMIFS(MRet[[#All],[CHARGE]],MRet[[#All],[DATE]],$A12,MRet[[#All],[Manual/ OutSale]],"Manual")) -> 0 | N12: =(SUMIFS(msi[[#All],[GC/ OTHERS]],msi[[#All],[DATE]],$A12,msi[[#All],[Manual /OutSale]],"Manual"))-(SUMIFS(MRet[[#All],[GC/ OTHERS]],MRet[[#All],[DATE]],$A12,MRet[[#All],[Manual/ OutSale]],"Manual")) -> 0 | S12: =(SUMIFS(msi[[#All],[Check]],msi[[#All],[DATE]],$A12,msi[[#All],[Manual /OutSale]],"Manual"))-(SUMIFS(MRet[[#All],[Check]],MRet[[#All],[DATE]],$A12,MRet[[#All],[Manual/ OutSale]],"Manual")) -> 0 | T12: =(SUMIFS(msi[[#All],[COD]],msi[[#All],[DATE]],$A12,msi[[#All],[Manual /OutSale]],"Manual"))-(SUMIFS(MRet[[#All],[COD]],MRet[[#All],[DATE]],$A12,MRet[[#All],[Manual/ OutSale]],"Manual")) -> 0 | U12: 0 | W12: =(SUMIFS(msi[[#All],[CWT]],msi[[#All],[DATE]],$A12,msi[[#All],[Manual /OutSale]],"Manual"))-(SUMIFS(MRet[[#All],[CWT]],MRet[[#All],[DATE]],$A12,MRet[[#All],[Manual/ OutSale]],"Manual")) -> 0 | X12: =(SUMIFS(msi[[#All],[CASH]],msi[[#All],[DATE]],$A12,msi[[#All],[Manual /OutSale]],"Manual"))-(SUMIFS(MRet[[#All],[CASH]],MRet[[#All],[DATE]],$A12,MRet[[#All],[Manual/ OutSale]],"Manual")) -> 0 | Y12: =D12-M12-N12+O12+Q12+R12-S12-T12-U12-V12-W12 -> 0 | Z12: =X12-Y12 -> 0
A13: =A12+1 -> 46303 | B13: =(SUMIFS(msi[[#All],[SP]],msi[[#All],[DATE]],$A13,msi[[#All],[Manual /OutSale]],"Manual"))-(SUMIFS(MRet[[#All],[SP]],MRet[[#All],[DATE]],$A13,MRet[[#All],[Manual/ OutSale]],"Manual")) -> 0 | C13: =(SUMIFS(msi[[#All],[DISC. AMOUNT]],msi[[#All],[DATE]],$A13,msi[[#All],[Manual /OutSale]],"Manual"))-(SUMIFS(MRet[[#All],[DISC. AMOUNT]],MRet[[#All],[DATE]],$A13,MRet[[#All],[Manual/ OutSale]],"Manual")) -> 0 | D13: =+B13-C13 -> 0 | F13: =+C13-E13 -> 0 | I13: =SUMIF(Z13,"<.01") -> 0 | J13: =SUMIF(Z13,">.01") -> 0 | M13: =(SUMIFS(msi[[#All],[CHARGE]],msi[[#All],[DATE]],$A13,msi[[#All],[Manual /OutSale]],"Manual"))-(SUMIFS(MRet[[#All],[CHARGE]],MRet[[#All],[DATE]],$A13,MRet[[#All],[Manual/ OutSale]],"Manual")) -> 0 | N13: =(SUMIFS(msi[[#All],[GC/ OTHERS]],msi[[#All],[DATE]],$A13,msi[[#All],[Manual /OutSale]],"Manual"))-(SUMIFS(MRet[[#All],[GC/ OTHERS]],MRet[[#All],[DATE]],$A13,MRet[[#All],[Manual/ OutSale]],"Manual")) -> 0 | S13: =(SUMIFS(msi[[#All],[Check]],msi[[#All],[DATE]],$A13,msi[[#All],[Manual /OutSale]],"Manual"))-(SUMIFS(MRet[[#All],[Check]],MRet[[#All],[DATE]],$A13,MRet[[#All],[Manual/ OutSale]],"Manual")) -> 0 | T13: =(SUMIFS(msi[[#All],[COD]],msi[[#All],[DATE]],$A13,msi[[#All],[Manual /OutSale]],"Manual"))-(SUMIFS(MRet[[#All],[COD]],MRet[[#All],[DATE]],$A13,MRet[[#All],[Manual/ OutSale]],"Manual")) -> 0 | U13: 0 | W13: =(SUMIFS(msi[[#All],[CWT]],msi[[#All],[DATE]],$A13,msi[[#All],[Manual /OutSale]],"Manual"))-(SUMIFS(MRet[[#All],[CWT]],MRet[[#All],[DATE]],$A13,MRet[[#All],[Manual/ OutSale]],"Manual")) -> 0 | X13: =(SUMIFS(msi[[#All],[CASH]],msi[[#All],[DATE]],$A13,msi[[#All],[Manual /OutSale]],"Manual"))-(SUMIFS(MRet[[#All],[CASH]],MRet[[#All],[DATE]],$A13,MRet[[#All],[Manual/ OutSale]],"Manual")) -> 0 | Y13: =D13-M13-N13+O13+Q13+R13-S13-T13-U13-V13-W13 -> 0 | Z13: =X13-Y13 -> 0
A14: =A13+1 -> 46304 | B14: =(SUMIFS(msi[[#All],[SP]],msi[[#All],[DATE]],$A14,msi[[#All],[Manual /OutSale]],"Manual"))-(SUMIFS(MRet[[#All],[SP]],MRet[[#All],[DATE]],$A14,MRet[[#All],[Manual/ OutSale]],"Manual")) -> 0 | C14: =(SUMIFS(msi[[#All],[DISC. AMOUNT]],msi[[#All],[DATE]],$A14,msi[[#All],[Manual /OutSale]],"Manual"))-(SUMIFS(MRet[[#All],[DISC. AMOUNT]],MRet[[#All],[DATE]],$A14,MRet[[#All],[Manual/ OutSale]],"Manual")) -> 0 | D14: =+B14-C14 -> 0 | F14: =+C14-E14 -> 0 | I14: =SUMIF(Z14,"<.01") -> 0 | J14: =SUMIF(Z14,">.01") -> 0 | M14: =(SUMIFS(msi[[#All],[CHARGE]],msi[[#All],[DATE]],$A14,msi[[#All],[Manual /OutSale]],"Manual"))-(SUMIFS(MRet[[#All],[CHARGE]],MRet[[#All],[DATE]],$A14,MRet[[#All],[Manual/ OutSale]],"Manual")) -> 0 | N14: =(SUMIFS(msi[[#All],[GC/ OTHERS]],msi[[#All],[DATE]],$A14,msi[[#All],[Manual /OutSale]],"Manual"))-(SUMIFS(MRet[[#All],[GC/ OTHERS]],MRet[[#All],[DATE]],$A14,MRet[[#All],[Manual/ OutSale]],"Manual")) -> 0 | S14: =(SUMIFS(msi[[#All],[Check]],msi[[#All],[DATE]],$A14,msi[[#All],[Manual /OutSale]],"Manual"))-(SUMIFS(MRet[[#All],[Check]],MRet[[#All],[DATE]],$A14,MRet[[#All],[Manual/ OutSale]],"Manual")) -> 0 | T14: =(SUMIFS(msi[[#All],[COD]],msi[[#All],[DATE]],$A14,msi[[#All],[Manual /OutSale]],"Manual"))-(SUMIFS(MRet[[#All],[COD]],MRet[[#All],[DATE]],$A14,MRet[[#All],[Manual/ OutSale]],"Manual")) -> 0 | U14: 0 | W14: =(SUMIFS(msi[[#All],[CWT]],msi[[#All],[DATE]],$A14,msi[[#All],[Manual /OutSale]],"Manual"))-(SUMIFS(MRet[[#All],[CWT]],MRet[[#All],[DATE]],$A14,MRet[[#All],[Manual/ OutSale]],"Manual")) -> 0 | X14: =(SUMIFS(msi[[#All],[CASH]],msi[[#All],[DATE]],$A14,msi[[#All],[Manual /OutSale]],"Manual"))-(SUMIFS(MRet[[#All],[CASH]],MRet[[#All],[DATE]],$A14,MRet[[#All],[Manual/ OutSale]],"Manual")) -> 0 | Y14: =D14-M14-N14+O14+Q14+R14-S14-T14-U14-V14-W14 -> 0 | Z14: =X14-Y14 -> 0
A15: =A14+1 -> 46305 | B15: =(SUMIFS(msi[[#All],[SP]],msi[[#All],[DATE]],$A15,msi[[#All],[Manual /OutSale]],"Manual"))-(SUMIFS(MRet[[#All],[SP]],MRet[[#All],[DATE]],$A15,MRet[[#All],[Manual/ OutSale]],"Manual")) -> 0 | C15: =(SUMIFS(msi[[#All],[DISC. AMOUNT]],msi[[#All],[DATE]],$A15,msi[[#All],[Manual /OutSale]],"Manual"))-(SUMIFS(MRet[[#All],[DISC. AMOUNT]],MRet[[#All],[DATE]],$A15,MRet[[#All],[Manual/ OutSale]],"Manual")) -> 0 | D15: =+B15-C15 -> 0 | F15: =+C15-E15 -> 0 | I15: =SUMIF(Z15,"<.01") -> 0 | J15: =SUMIF(Z15,">.01") -> 0 | M15: =(SUMIFS(msi[[#All],[CHARGE]],msi[[#All],[DATE]],$A15,msi[[#All],[Manual /OutSale]],"Manual"))-(SUMIFS(MRet[[#All],[CHARGE]],MRet[[#All],[DATE]],$A15,MRet[[#All],[Manual/ OutSale]],"Manual")) -> 0 | N15: =(SUMIFS(msi[[#All],[GC/ OTHERS]],msi[[#All],[DATE]],$A15,msi[[#All],[Manual /OutSale]],"Manual"))-(SUMIFS(MRet[[#All],[GC/ OTHERS]],MRet[[#All],[DATE]],$A15,MRet[[#All],[Manual/ OutSale]],"Manual")) -> 0 | S15: =(SUMIFS(msi[[#All],[Check]],msi[[#All],[DATE]],$A15,msi[[#All],[Manual /OutSale]],"Manual"))-(SUMIFS(MRet[[#All],[Check]],MRet[[#All],[DATE]],$A15,MRet[[#All],[Manual/ OutSale]],"Manual")) -> 0 | T15: =(SUMIFS(msi[[#All],[COD]],msi[[#All],[DATE]],$A15,msi[[#All],[Manual /OutSale]],"Manual"))-(SUMIFS(MRet[[#All],[COD]],MRet[[#All],[DATE]],$A15,MRet[[#All],[Manual/ OutSale]],"Manual")) -> 0 | U15: 0 | W15: =(SUMIFS(msi[[#All],[CWT]],msi[[#All],[DATE]],$A15,msi[[#All],[Manual /OutSale]],"Manual"))-(SUMIFS(MRet[[#All],[CWT]],MRet[[#All],[DATE]],$A15,MRet[[#All],[Manual/ OutSale]],"Manual")) -> 0 | X15: =(SUMIFS(msi[[#All],[CASH]],msi[[#All],[DATE]],$A15,msi[[#All],[Manual /OutSale]],"Manual"))-(SUMIFS(MRet[[#All],[CASH]],MRet[[#All],[DATE]],$A15,MRet[[#All],[Manual/ OutSale]],"Manual")) -> 0 | Y15: =D15-M15-N15+O15+Q15+R15-S15-T15-U15-V15-W15 -> 0 | Z15: =X15-Y15 -> 0
A16: =A15+1 -> 46306 | B16: =(SUMIFS(msi[[#All],[SP]],msi[[#All],[DATE]],$A16,msi[[#All],[Manual /OutSale]],"Manual"))-(SUMIFS(MRet[[#All],[SP]],MRet[[#All],[DATE]],$A16,MRet[[#All],[Manual/ OutSale]],"Manual")) -> 0 | C16: =(SUMIFS(msi[[#All],[DISC. AMOUNT]],msi[[#All],[DATE]],$A16,msi[[#All],[Manual /OutSale]],"Manual"))-(SUMIFS(MRet[[#All],[DISC. AMOUNT]],MRet[[#All],[DATE]],$A16,MRet[[#All],[Manual/ OutSale]],"Manual")) -> 0 | D16: =+B16-C16 -> 0 | F16: =+C16-E16 -> 0 | I16: =SUMIF(Z16,"<.01") -> 0 | J16: =SUMIF(Z16,">.01") -> 0 | M16: =(SUMIFS(msi[[#All],[CHARGE]],msi[[#All],[DATE]],$A16,msi[[#All],[Manual /OutSale]],"Manual"))-(SUMIFS(MRet[[#All],[CHARGE]],MRet[[#All],[DATE]],$A16,MRet[[#All],[Manual/ OutSale]],"Manual")) -> 0 | N16: =(SUMIFS(msi[[#All],[GC/ OTHERS]],msi[[#All],[DATE]],$A16,msi[[#All],[Manual /OutSale]],"Manual"))-(SUMIFS(MRet[[#All],[GC/ OTHERS]],MRet[[#All],[DATE]],$A16,MRet[[#All],[Manual/ OutSale]],"Manual")) -> 0 | S16: =(SUMIFS(msi[[#All],[Check]],msi[[#All],[DATE]],$A16,msi[[#All],[Manual /OutSale]],"Manual"))-(SUMIFS(MRet[[#All],[Check]],MRet[[#All],[DATE]],$A16,MRet[[#All],[Manual/ OutSale]],"Manual")) -> 0 | T16: =(SUMIFS(msi[[#All],[COD]],msi[[#All],[DATE]],$A16,msi[[#All],[Manual /OutSale]],"Manual"))-(SUMIFS(MRet[[#All],[COD]],MRet[[#All],[DATE]],$A16,MRet[[#All],[Manual/ OutSale]],"Manual")) -> 0 | U16: 0 | W16: =(SUMIFS(msi[[#All],[CWT]],msi[[#All],[DATE]],$A16,msi[[#All],[Manual /OutSale]],"Manual"))-(SUMIFS(MRet[[#All],[CWT]],MRet[[#All],[DATE]],$A16,MRet[[#All],[Manual/ OutSale]],"Manual")) -> 0 | X16: =(SUMIFS(msi[[#All],[CASH]],msi[[#All],[DATE]],$A16,msi[[#All],[Manual /OutSale]],"Manual"))-(SUMIFS(MRet[[#All],[CASH]],MRet[[#All],[DATE]],$A16,MRet[[#All],[Manual/ OutSale]],"Manual")) -> 0 | Y16: =D16-M16-N16+O16+Q16+R16-S16-T16-U16-V16-W16 -> 0 | Z16: =X16-Y16 -> 0
A17: =A16+1 -> 46307 | B17: =(SUMIFS(msi[[#All],[SP]],msi[[#All],[DATE]],$A17,msi[[#All],[Manual /OutSale]],"Manual"))-(SUMIFS(MRet[[#All],[SP]],MRet[[#All],[DATE]],$A17,MRet[[#All],[Manual/ OutSale]],"Manual")) -> 0 | C17: =(SUMIFS(msi[[#All],[DISC. AMOUNT]],msi[[#All],[DATE]],$A17,msi[[#All],[Manual /OutSale]],"Manual"))-(SUMIFS(MRet[[#All],[DISC. AMOUNT]],MRet[[#All],[DATE]],$A17,MRet[[#All],[Manual/ OutSale]],"Manual")) -> 0 | D17: =+B17-C17 -> 0 | F17: =+C17-E17 -> 0 | I17: =SUMIF(Z17,"<.01") -> 0 | J17: =SUMIF(Z17,">.01") -> 0 | M17: =(SUMIFS(msi[[#All],[CHARGE]],msi[[#All],[DATE]],$A17,msi[[#All],[Manual /OutSale]],"Manual"))-(SUMIFS(MRet[[#All],[CHARGE]],MRet[[#All],[DATE]],$A17,MRet[[#All],[Manual/ OutSale]],"Manual")) -> 0 | N17: =(SUMIFS(msi[[#All],[GC/ OTHERS]],msi[[#All],[DATE]],$A17,msi[[#All],[Manual /OutSale]],"Manual"))-(SUMIFS(MRet[[#All],[GC/ OTHERS]],MRet[[#All],[DATE]],$A17,MRet[[#All],[Manual/ OutSale]],"Manual")) -> 0 | S17: =(SUMIFS(msi[[#All],[Check]],msi[[#All],[DATE]],$A17,msi[[#All],[Manual /OutSale]],"Manual"))-(SUMIFS(MRet[[#All],[Check]],MRet[[#All],[DATE]],$A17,MRet[[#All],[Manual/ OutSale]],"Manual")) -> 0 | T17: =(SUMIFS(msi[[#All],[COD]],msi[[#All],[DATE]],$A17,msi[[#All],[Manual /OutSale]],"Manual"))-(SUMIFS(MRet[[#All],[COD]],MRet[[#All],[DATE]],$A17,MRet[[#All],[Manual/ OutSale]],"Manual")) -> 0 | U17: 0 | W17: =(SUMIFS(msi[[#All],[CWT]],msi[[#All],[DATE]],$A17,msi[[#All],[Manual /OutSale]],"Manual"))-(SUMIFS(MRet[[#All],[CWT]],MRet[[#All],[DATE]],$A17,MRet[[#All],[Manual/ OutSale]],"Manual")) -> 0 | X17: =(SUMIFS(msi[[#All],[CASH]],msi[[#All],[DATE]],$A17,msi[[#All],[Manual /OutSale]],"Manual"))-(SUMIFS(MRet[[#All],[CASH]],MRet[[#All],[DATE]],$A17,MRet[[#All],[Manual/ OutSale]],"Manual")) -> 0 | Y17: =D17-M17-N17+O17+Q17+R17-S17-T17-U17-V17-W17 -> 0 | Z17: =X17-Y17 -> 0
A18: =A17+1 -> 46308 | B18: =(SUMIFS(msi[[#All],[SP]],msi[[#All],[DATE]],$A18,msi[[#All],[Manual /OutSale]],"Manual"))-(SUMIFS(MRet[[#All],[SP]],MRet[[#All],[DATE]],$A18,MRet[[#All],[Manual/ OutSale]],"Manual")) -> 0 | C18: =(SUMIFS(msi[[#All],[DISC. AMOUNT]],msi[[#All],[DATE]],$A18,msi[[#All],[Manual /OutSale]],"Manual"))-(SUMIFS(MRet[[#All],[DISC. AMOUNT]],MRet[[#All],[DATE]],$A18,MRet[[#All],[Manual/ OutSale]],"Manual")) -> 0 | D18: =+B18-C18 -> 0 | F18: =+C18-E18 -> 0 | I18: =SUMIF(Z18,"<.01") -> 0 | J18: =SUMIF(Z18,">.01") -> 0 | M18: =(SUMIFS(msi[[#All],[CHARGE]],msi[[#All],[DATE]],$A18,msi[[#All],[Manual /OutSale]],"Manual"))-(SUMIFS(MRet[[#All],[CHARGE]],MRet[[#All],[DATE]],$A18,MRet[[#All],[Manual/ OutSale]],"Manual")) -> 0 | N18: =(SUMIFS(msi[[#All],[GC/ OTHERS]],msi[[#All],[DATE]],$A18,msi[[#All],[Manual /OutSale]],"Manual"))-(SUMIFS(MRet[[#All],[GC/ OTHERS]],MRet[[#All],[DATE]],$A18,MRet[[#All],[Manual/ OutSale]],"Manual")) -> 0 | S18: =(SUMIFS(msi[[#All],[Check]],msi[[#All],[DATE]],$A18,msi[[#All],[Manual /OutSale]],"Manual"))-(SUMIFS(MRet[[#All],[Check]],MRet[[#All],[DATE]],$A18,MRet[[#All],[Manual/ OutSale]],"Manual")) -> 0 | T18: =(SUMIFS(msi[[#All],[COD]],msi[[#All],[DATE]],$A18,msi[[#All],[Manual /OutSale]],"Manual"))-(SUMIFS(MRet[[#All],[COD]],MRet[[#All],[DATE]],$A18,MRet[[#All],[Manual/ OutSale]],"Manual")) -> 0 | U18: 0 | W18: =(SUMIFS(msi[[#All],[CWT]],msi[[#All],[DATE]],$A18,msi[[#All],[Manual /OutSale]],"Manual"))-(SUMIFS(MRet[[#All],[CWT]],MRet[[#All],[DATE]],$A18,MRet[[#All],[Manual/ OutSale]],"Manual")) -> 0 | X18: =(SUMIFS(msi[[#All],[CASH]],msi[[#All],[DATE]],$A18,msi[[#All],[Manual /OutSale]],"Manual"))-(SUMIFS(MRet[[#All],[CASH]],MRet[[#All],[DATE]],$A18,MRet[[#All],[Manual/ OutSale]],"Manual")) -> 0 | Y18: =D18-M18-N18+O18+Q18+R18-S18-T18-U18-V18-W18 -> 0 | Z18: =X18-Y18 -> 0
... A20: =A19+1 -> 46310 | B20: =(SUMIFS(msi[[#All],[SP]],msi[[#All],[DATE]],$A20,msi[[#All],[Manual /OutSale]],"Manual"))-(SUMIFS(MRet[[#All],[SP]],MRet[[#All],[DATE]],$A20,MRet[[#All],[Manual/ OutSale]],"Manual")) -> 0 | C20: =(SUMIFS(msi[[#All],[DISC. AMOUNT]],msi[[#All],[DATE]],$A20,msi[[#All],[Manual /OutSale]],"Manual"))-(SUMIFS(MRet[[#All],[DISC. AMOUNT]],MRet[[#All],[DATE]],$A20,MRet[[#All],[Manual/ OutSale]],"Manual")) -> 0 | D20: =+B20-C20 -> 0 | F20: =+C20-E20 -> 0 | I20: =SUMIF(Z20,"<.01") -> 0 | J20: =SUMIF(Z20,">.01") -> 0 | M20: =(SUMIFS(msi[[#All],[CHARGE]],msi[[#All],[DATE]],$A20,msi[[#All],[Manual /OutSale]],"Manual"))-(SUMIFS(MRet[[#All],[CHARGE]],MRet[[#All],[DATE]],$A20,MRet[[#All],[Manual/ OutSale]],"Manual")) -> 0 | N20: =(SUMIFS(msi[[#All],[GC/ OTHERS]],msi[[#All],[DATE]],$A20,msi[[#All],[Manual /OutSale]],"Manual"))-(SUMIFS(MRet[[#All],[GC/ OTHERS]],MRet[[#All],[DATE]],$A20,MRet[[#All],[Manual/ OutSale]],"Manual")) -> 0 | S20: =(SUMIFS(msi[[#All],[Check]],msi[[#All],[DATE]],$A20,msi[[#All],[Manual /OutSale]],"Manual"))-(SUMIFS(MRet[[#All],[Check]],MRet[[#All],[DATE]],$A20,MRet[[#All],[Manual/ OutSale]],"Manual")) -> 0 | T20: =(SUMIFS(msi[[#All],[COD]],msi[[#All],[DATE]],$A20,msi[[#All],[Manual /OutSale]],"Manual"))-(SUMIFS(MRet[[#All],[COD]],MRet[[#All],[DATE]],$A20,MRet[[#All],[Manual/ OutSale]],"Manual")) -> 0 | U20: 0 | W20: =(SUMIFS(msi[[#All],[CWT]],msi[[#All],[DATE]],$A20,msi[[#All],[Manual /OutSale]],"Manual"))-(SUMIFS(MRet[[#All],[CWT]],MRet[[#All],[DATE]],$A20,MRet[[#All],[Manual/ OutSale]],"Manual")) -> 0 | X20: =(SUMIFS(msi[[#All],[CASH]],msi[[#All],[DATE]],$A20,msi[[#All],[Manual /OutSale]],"Manual"))-(SUMIFS(MRet[[#All],[CASH]],MRet[[#All],[DATE]],$A20,MRet[[#All],[Manual/ OutSale]],"Manual")) -> 0 | Y20: =D20-M20-N20+O20+Q20+R20-S20-T20-U20-V20-W20 -> 0 | Z20: =X20-Y20 -> 0
B21: =SUM(B6:B20) -> 0 | C21: =SUM(C6:C20) -> 0 | D21: =SUM(D6:D20) -> 0 | E21: =SUM(E6:E20) -> 0 | F21: =SUM(F6:F20) -> 0 | G21: =SUM(G6:G20) -> 0 | H21: =SUM(H6:H20) -> 0 | I21: =SUM(I6:I20) -> 0 | ... K21: =SUM(K6:K20) -> 0 | M21: =SUM(M6:M20) -> 0 | N21: =SUM(N6:N20) -> 0 | O21: =SUM(O6:O20) -> 0 | P21: =SUM(P6:P20) -> 0 | Q21: =SUM(Q6:Q20) -> 0 | R21: =SUM(R6:R20) -> 0 | S21: =SUM(S6:S20) -> 0 | T21: =SUM(T6:T20) -> 0 | ... Z21: =SUM(Z6:Z20) -> 0
A23: =A20+1 -> 46311 | B23: =(SUMIFS(msi[[#All],[SP]],msi[[#All],[DATE]],$A23,msi[[#All],[Manual /OutSale]],"Manual"))-(SUMIFS(MRet[[#All],[SP]],MRet[[#All],[DATE]],$A23,MRet[[#All],[Manual/ OutSale]],"Manual")) -> 0 | C23: =(SUMIFS(msi[[#All],[DISC. AMOUNT]],msi[[#All],[DATE]],$A23,msi[[#All],[Manual /OutSale]],"Manual"))-(SUMIFS(MRet[[#All],[DISC. AMOUNT]],MRet[[#All],[DATE]],$A23,MRet[[#All],[Manual/ OutSale]],"Manual")) -> 0 | D23: =+B23-C23 -> 0 | F23: =+C23-E23 -> 0 | I23: =SUMIF(Z23,"<.01") -> 0 | J23: =SUMIF(Z23,">.01") -> 0 | M23: =(SUMIFS(msi[[#All],[CHARGE]],msi[[#All],[DATE]],$A23,msi[[#All],[Manual /OutSale]],"Manual"))-(SUMIFS(MRet[[#All],[CHARGE]],MRet[[#All],[DATE]],$A23,MRet[[#All],[Manual/ OutSale]],"Manual")) -> 0 | N23: =(SUMIFS(msi[[#All],[GC/ OTHERS]],msi[[#All],[DATE]],$A23,msi[[#All],[Manual /OutSale]],"Manual"))-(SUMIFS(MRet[[#All],[GC/ OTHERS]],MRet[[#All],[DATE]],$A23,MRet[[#All],[Manual/ OutSale]],"Manual")) -> 0 | S23: =(SUMIFS(msi[[#All],[Check]],msi[[#All],[DATE]],$A23,msi[[#All],[Manual /OutSale]],"Manual"))-(SUMIFS(MRet[[#All],[Check]],MRet[[#All],[DATE]],$A23,MRet[[#All],[Manual/ OutSale]],"Manual")) -> 0 | T23: =(SUMIFS(msi[[#All],[COD]],msi[[#All],[DATE]],$A23,msi[[#All],[Manual /OutSale]],"Manual"))-(SUMIFS(MRet[[#All],[COD]],MRet[[#All],[DATE]],$A23,MRet[[#All],[Manual/ OutSale]],"Manual")) -> 0 | U23: 0 | W23: =(SUMIFS(msi[[#All],[CWT]],msi[[#All],[DATE]],$A23,msi[[#All],[Manual /OutSale]],"Manual"))-(SUMIFS(MRet[[#All],[CWT]],MRet[[#All],[DATE]],$A23,MRet[[#All],[Manual/ OutSale]],"Manual")) -> 0 | X23: =(SUMIFS(msi[[#All],[CASH]],msi[[#All],[DATE]],$A23,msi[[#All],[Manual /OutSale]],"Manual"))-(SUMIFS(MRet[[#All],[CASH]],MRet[[#All],[DATE]],$A23,MRet[[#All],[Manual/ OutSale]],"Manual")) -> 0 | Y23: =D23-M23-N23+O23+Q23+R23-S23-T23-U23-V23-W23 -> 0 | Z23: =X23-Y23 -> 0
A24: =A23+1 -> 46312 | B24: =(SUMIFS(msi[[#All],[SP]],msi[[#All],[DATE]],$A24,msi[[#All],[Manual /OutSale]],"Manual"))-(SUMIFS(MRet[[#All],[SP]],MRet[[#All],[DATE]],$A24,MRet[[#All],[Manual/ OutSale]],"Manual")) -> 0 | C24: =(SUMIFS(msi[[#All],[DISC. AMOUNT]],msi[[#All],[DATE]],$A24,msi[[#All],[Manual /OutSale]],"Manual"))-(SUMIFS(MRet[[#All],[DISC. AMOUNT]],MRet[[#All],[DATE]],$A24,MRet[[#All],[Manual/ OutSale]],"Manual")) -> 0 | D24: =+B24-C24 -> 0 | F24: =+C24-E24 -> 0 | I24: =SUMIF(Z24,"<.01") -> 0 | J24: =SUMIF(Z24,">.01") -> 0 | M24: =(SUMIFS(msi[[#All],[CHARGE]],msi[[#All],[DATE]],$A24,msi[[#All],[Manual /OutSale]],"Manual"))-(SUMIFS(MRet[[#All],[CHARGE]],MRet[[#All],[DATE]],$A24,MRet[[#All],[Manual/ OutSale]],"Manual")) -> 0 | N24: =(SUMIFS(msi[[#All],[GC/ OTHERS]],msi[[#All],[DATE]],$A24,msi[[#All],[Manual /OutSale]],"Manual"))-(SUMIFS(MRet[[#All],[GC/ OTHERS]],MRet[[#All],[DATE]],$A24,MRet[[#All],[Manual/ OutSale]],"Manual")) -> 0 | S24: =(SUMIFS(msi[[#All],[Check]],msi[[#All],[DATE]],$A24,msi[[#All],[Manual /OutSale]],"Manual"))-(SUMIFS(MRet[[#All],[Check]],MRet[[#All],[DATE]],$A24,MRet[[#All],[Manual/ OutSale]],"Manual")) -> 0 | T24: =(SUMIFS(msi[[#All],[COD]],msi[[#All],[DATE]],$A24,msi[[#All],[Manual /OutSale]],"Manual"))-(SUMIFS(MRet[[#All],[COD]],MRet[[#All],[DATE]],$A24,MRet[[#All],[Manual/ OutSale]],"Manual")) -> 0 | U24: 0 | W24: =(SUMIFS(msi[[#All],[CWT]],msi[[#All],[DATE]],$A24,msi[[#All],[Manual /OutSale]],"Manual"))-(SUMIFS(MRet[[#All],[CWT]],MRet[[#All],[DATE]],$A24,MRet[[#All],[Manual/ OutSale]],"Manual")) -> 0 | X24: =(SUMIFS(msi[[#All],[CASH]],msi[[#All],[DATE]],$A24,msi[[#All],[Manual /OutSale]],"Manual"))-(SUMIFS(MRet[[#All],[CASH]],MRet[[#All],[DATE]],$A24,MRet[[#All],[Manual/ OutSale]],"Manual")) -> 0 | Y24: =D24-M24-N24+O24+Q24+R24-S24-T24-U24-V24-W24 -> 0 | Z24: =X24-Y24 -> 0
A25: =A24+1 -> 46313 | B25: =(SUMIFS(msi[[#All],[SP]],msi[[#All],[DATE]],$A25,msi[[#All],[Manual /OutSale]],"Manual"))-(SUMIFS(MRet[[#All],[SP]],MRet[[#All],[DATE]],$A25,MRet[[#All],[Manual/ OutSale]],"Manual")) -> 0 | C25: =(SUMIFS(msi[[#All],[DISC. AMOUNT]],msi[[#All],[DATE]],$A25,msi[[#All],[Manual /OutSale]],"Manual"))-(SUMIFS(MRet[[#All],[DISC. AMOUNT]],MRet[[#All],[DATE]],$A25,MRet[[#All],[Manual/ OutSale]],"Manual")) -> 0 | D25: =+B25-C25 -> 0 | F25: =+C25-E25 -> 0 | I25: =SUMIF(Z25,"<.01") -> 0 | J25: =SUMIF(Z25,">.01") -> 0 | M25: =(SUMIFS(msi[[#All],[CHARGE]],msi[[#All],[DATE]],$A25,msi[[#All],[Manual /OutSale]],"Manual"))-(SUMIFS(MRet[[#All],[CHARGE]],MRet[[#All],[DATE]],$A25,MRet[[#All],[Manual/ OutSale]],"Manual")) -> 0 | N25: =(SUMIFS(msi[[#All],[GC/ OTHERS]],msi[[#All],[DATE]],$A25,msi[[#All],[Manual /OutSale]],"Manual"))-(SUMIFS(MRet[[#All],[GC/ OTHERS]],MRet[[#All],[DATE]],$A25,MRet[[#All],[Manual/ OutSale]],"Manual")) -> 0 | S25: =(SUMIFS(msi[[#All],[Check]],msi[[#All],[DATE]],$A25,msi[[#All],[Manual /OutSale]],"Manual"))-(SUMIFS(MRet[[#All],[Check]],MRet[[#All],[DATE]],$A25,MRet[[#All],[Manual/ OutSale]],"Manual")) -> 0 | T25: =(SUMIFS(msi[[#All],[COD]],msi[[#All],[DATE]],$A25,msi[[#All],[Manual /OutSale]],"Manual"))-(SUMIFS(MRet[[#All],[COD]],MRet[[#All],[DATE]],$A25,MRet[[#All],[Manual/ OutSale]],"Manual")) -> 0 | U25: 0 | W25: =(SUMIFS(msi[[#All],[CWT]],msi[[#All],[DATE]],$A25,msi[[#All],[Manual /OutSale]],"Manual"))-(SUMIFS(MRet[[#All],[CWT]],MRet[[#All],[DATE]],$A25,MRet[[#All],[Manual/ OutSale]],"Manual")) -> 0 | X25: =(SUMIFS(msi[[#All],[CASH]],msi[[#All],[DATE]],$A25,msi[[#All],[Manual /OutSale]],"Manual"))-(SUMIFS(MRet[[#All],[CASH]],MRet[[#All],[DATE]],$A25,MRet[[#All],[Manual/ OutSale]],"Manual")) -> 0 | Y25: =D25-M25-N25+O25+Q25+R25-S25-T25-U25-V25-W25 -> 0 | Z25: =X25-Y25 -> 0
A26: =A25+1 -> 46314 | B26: =(SUMIFS(msi[[#All],[SP]],msi[[#All],[DATE]],$A26,msi[[#All],[Manual /OutSale]],"Manual"))-(SUMIFS(MRet[[#All],[SP]],MRet[[#All],[DATE]],$A26,MRet[[#All],[Manual/ OutSale]],"Manual")) -> 0 | C26: =(SUMIFS(msi[[#All],[DISC. AMOUNT]],msi[[#All],[DATE]],$A26,msi[[#All],[Manual /OutSale]],"Manual"))-(SUMIFS(MRet[[#All],[DISC. AMOUNT]],MRet[[#All],[DATE]],$A26,MRet[[#All],[Manual/ OutSale]],"Manual")) -> 0 | D26: =+B26-C26 -> 0 | F26: =+C26-E26 -> 0 | I26: =SUMIF(Z26,"<.01") -> 0 | J26: =SUMIF(Z26,">.01") -> 0 | M26: =(SUMIFS(msi[[#All],[CHARGE]],msi[[#All],[DATE]],$A26,msi[[#All],[Manual /OutSale]],"Manual"))-(SUMIFS(MRet[[#All],[CHARGE]],MRet[[#All],[DATE]],$A26,MRet[[#All],[Manual/ OutSale]],"Manual")) -> 0 | N26: =(SUMIFS(msi[[#All],[GC/ OTHERS]],msi[[#All],[DATE]],$A26,msi[[#All],[Manual /OutSale]],"Manual"))-(SUMIFS(MRet[[#All],[GC/ OTHERS]],MRet[[#All],[DATE]],$A26,MRet[[#All],[Manual/ OutSale]],"Manual")) -> 0 | S26: =(SUMIFS(msi[[#All],[Check]],msi[[#All],[DATE]],$A26,msi[[#All],[Manual /OutSale]],"Manual"))-(SUMIFS(MRet[[#All],[Check]],MRet[[#All],[DATE]],$A26,MRet[[#All],[Manual/ OutSale]],"Manual")) -> 0 | T26: =(SUMIFS(msi[[#All],[COD]],msi[[#All],[DATE]],$A26,msi[[#All],[Manual /OutSale]],"Manual"))-(SUMIFS(MRet[[#All],[COD]],MRet[[#All],[DATE]],$A26,MRet[[#All],[Manual/ OutSale]],"Manual")) -> 0 | U26: 0 | W26: =(SUMIFS(msi[[#All],[CWT]],msi[[#All],[DATE]],$A26,msi[[#All],[Manual /OutSale]],"Manual"))-(SUMIFS(MRet[[#All],[CWT]],MRet[[#All],[DATE]],$A26,MRet[[#All],[Manual/ OutSale]],"Manual")) -> 0 | X26: =(SUMIFS(msi[[#All],[CASH]],msi[[#All],[DATE]],$A26,msi[[#All],[Manual /OutSale]],"Manual"))-(SUMIFS(MRet[[#All],[CASH]],MRet[[#All],[DATE]],$A26,MRet[[#All],[Manual/ OutSale]],"Manual")) -> 0 | Y26: =D26-M26-N26+O26+Q26+R26-S26-T26-U26-V26-W26 -> 0 | Z26: =X26-Y26 -> 0
A27: =A26+1 -> 46315 | B27: =(SUMIFS(msi[[#All],[SP]],msi[[#All],[DATE]],$A27,msi[[#All],[Manual /OutSale]],"Manual"))-(SUMIFS(MRet[[#All],[SP]],MRet[[#All],[DATE]],$A27,MRet[[#All],[Manual/ OutSale]],"Manual")) -> 0 | C27: =(SUMIFS(msi[[#All],[DISC. AMOUNT]],msi[[#All],[DATE]],$A27,msi[[#All],[Manual /OutSale]],"Manual"))-(SUMIFS(MRet[[#All],[DISC. AMOUNT]],MRet[[#All],[DATE]],$A27,MRet[[#All],[Manual/ OutSale]],"Manual")) -> 0 | D27: =+B27-C27 -> 0 | F27: =+C27-E27 -> 0 | I27: =SUMIF(Z27,"<.01") -> 0 | J27: =SUMIF(Z27,">.01") -> 0 | M27: =(SUMIFS(msi[[#All],[CHARGE]],msi[[#All],[DATE]],$A27,msi[[#All],[Manual /OutSale]],"Manual"))-(SUMIFS(MRet[[#All],[CHARGE]],MRet[[#All],[DATE]],$A27,MRet[[#All],[Manual/ OutSale]],"Manual")) -> 0 | N27: =(SUMIFS(msi[[#All],[GC/ OTHERS]],msi[[#All],[DATE]],$A27,msi[[#All],[Manual /OutSale]],"Manual"))-(SUMIFS(MRet[[#All],[GC/ OTHERS]],MRet[[#All],[DATE]],$A27,MRet[[#All],[Manual/ OutSale]],"Manual")) -> 0 | S27: =(SUMIFS(msi[[#All],[Check]],msi[[#All],[DATE]],$A27,msi[[#All],[Manual /OutSale]],"Manual"))-(SUMIFS(MRet[[#All],[Check]],MRet[[#All],[DATE]],$A27,MRet[[#All],[Manual/ OutSale]],"Manual")) -> 0 | T27: =(SUMIFS(msi[[#All],[COD]],msi[[#All],[DATE]],$A27,msi[[#All],[Manual /OutSale]],"Manual"))-(SUMIFS(MRet[[#All],[COD]],MRet[[#All],[DATE]],$A27,MRet[[#All],[Manual/ OutSale]],"Manual")) -> 0 | U27: 0 | W27: =(SUMIFS(msi[[#All],[CWT]],msi[[#All],[DATE]],$A27,msi[[#All],[Manual /OutSale]],"Manual"))-(SUMIFS(MRet[[#All],[CWT]],MRet[[#All],[DATE]],$A27,MRet[[#All],[Manual/ OutSale]],"Manual")) -> 0 | X27: =(SUMIFS(msi[[#All],[CASH]],msi[[#All],[DATE]],$A27,msi[[#All],[Manual /OutSale]],"Manual"))-(SUMIFS(MRet[[#All],[CASH]],MRet[[#All],[DATE]],$A27,MRet[[#All],[Manual/ OutSale]],"Manual")) -> 0 | Y27: =D27-M27-N27+O27+Q27+R27-S27-T27-U27-V27-W27 -> 0 | Z27: =X27-Y27 -> 0
A28: =A27+1 -> 46316 | B28: =(SUMIFS(msi[[#All],[SP]],msi[[#All],[DATE]],$A28,msi[[#All],[Manual /OutSale]],"Manual"))-(SUMIFS(MRet[[#All],[SP]],MRet[[#All],[DATE]],$A28,MRet[[#All],[Manual/ OutSale]],"Manual")) -> 0 | C28: =(SUMIFS(msi[[#All],[DISC. AMOUNT]],msi[[#All],[DATE]],$A28,msi[[#All],[Manual /OutSale]],"Manual"))-(SUMIFS(MRet[[#All],[DISC. AMOUNT]],MRet[[#All],[DATE]],$A28,MRet[[#All],[Manual/ OutSale]],"Manual")) -> 0 | D28: =+B28-C28 -> 0 | F28: =+C28-E28 -> 0 | I28: =SUMIF(Z28,"<.01") -> 0 | J28: =SUMIF(Z28,">.01") -> 0 | M28: =(SUMIFS(msi[[#All],[CHARGE]],msi[[#All],[DATE]],$A28,msi[[#All],[Manual /OutSale]],"Manual"))-(SUMIFS(MRet[[#All],[CHARGE]],MRet[[#All],[DATE]],$A28,MRet[[#All],[Manual/ OutSale]],"Manual")) -> 0 | N28: =(SUMIFS(msi[[#All],[GC/ OTHERS]],msi[[#All],[DATE]],$A28,msi[[#All],[Manual /OutSale]],"Manual"))-(SUMIFS(MRet[[#All],[GC/ OTHERS]],MRet[[#All],[DATE]],$A28,MRet[[#All],[Manual/ OutSale]],"Manual")) -> 0 | S28: =(SUMIFS(msi[[#All],[Check]],msi[[#All],[DATE]],$A28,msi[[#All],[Manual /OutSale]],"Manual"))-(SUMIFS(MRet[[#All],[Check]],MRet[[#All],[DATE]],$A28,MRet[[#All],[Manual/ OutSale]],"Manual")) -> 0 | T28: =(SUMIFS(msi[[#All],[COD]],msi[[#All],[DATE]],$A28,msi[[#All],[Manual /OutSale]],"Manual"))-(SUMIFS(MRet[[#All],[COD]],MRet[[#All],[DATE]],$A28,MRet[[#All],[Manual/ OutSale]],"Manual")) -> 0 | U28: 0 | W28: =(SUMIFS(msi[[#All],[CWT]],msi[[#All],[DATE]],$A28,msi[[#All],[Manual /OutSale]],"Manual"))-(SUMIFS(MRet[[#All],[CWT]],MRet[[#All],[DATE]],$A28,MRet[[#All],[Manual/ OutSale]],"Manual")) -> 0 | X28: =(SUMIFS(msi[[#All],[CASH]],msi[[#All],[DATE]],$A28,msi[[#All],[Manual /OutSale]],"Manual"))-(SUMIFS(MRet[[#All],[CASH]],MRet[[#All],[DATE]],$A28,MRet[[#All],[Manual/ OutSale]],"Manual")) -> 0 | Y28: =D28-M28-N28+O28+Q28+R28-S28-T28-U28-V28-W28 -> 0 | Z28: =X28-Y28 -> 0
A29: =A28+1 -> 46317 | B29: =(SUMIFS(msi[[#All],[SP]],msi[[#All],[DATE]],$A29,msi[[#All],[Manual /OutSale]],"Manual"))-(SUMIFS(MRet[[#All],[SP]],MRet[[#All],[DATE]],$A29,MRet[[#All],[Manual/ OutSale]],"Manual")) -> 0 | C29: =(SUMIFS(msi[[#All],[DISC. AMOUNT]],msi[[#All],[DATE]],$A29,msi[[#All],[Manual /OutSale]],"Manual"))-(SUMIFS(MRet[[#All],[DISC. AMOUNT]],MRet[[#All],[DATE]],$A29,MRet[[#All],[Manual/ OutSale]],"Manual")) -> 0 | D29: =+B29-C29 -> 0 | F29: =+C29-E29 -> 0 | I29: =SUMIF(Z29,"<.01") -> 0 | J29: =SUMIF(Z29,">.01") -> 0 | M29: =(SUMIFS(msi[[#All],[CHARGE]],msi[[#All],[DATE]],$A29,msi[[#All],[Manual /OutSale]],"Manual"))-(SUMIFS(MRet[[#All],[CHARGE]],MRet[[#All],[DATE]],$A29,MRet[[#All],[Manual/ OutSale]],"Manual")) -> 0 | N29: =(SUMIFS(msi[[#All],[GC/ OTHERS]],msi[[#All],[DATE]],$A29,msi[[#All],[Manual /OutSale]],"Manual"))-(SUMIFS(MRet[[#All],[GC/ OTHERS]],MRet[[#All],[DATE]],$A29,MRet[[#All],[Manual/ OutSale]],"Manual")) -> 0 | S29: =(SUMIFS(msi[[#All],[Check]],msi[[#All],[DATE]],$A29,msi[[#All],[Manual /OutSale]],"Manual"))-(SUMIFS(MRet[[#All],[Check]],MRet[[#All],[DATE]],$A29,MRet[[#All],[Manual/ OutSale]],"Manual")) -> 0 | T29: =(SUMIFS(msi[[#All],[COD]],msi[[#All],[DATE]],$A29,msi[[#All],[Manual /OutSale]],"Manual"))-(SUMIFS(MRet[[#All],[COD]],MRet[[#All],[DATE]],$A29,MRet[[#All],[Manual/ OutSale]],"Manual")) -> 0 | U29: 0 | W29: =(SUMIFS(msi[[#All],[CWT]],msi[[#All],[DATE]],$A29,msi[[#All],[Manual /OutSale]],"Manual"))-(SUMIFS(MRet[[#All],[CWT]],MRet[[#All],[DATE]],$A29,MRet[[#All],[Manual/ OutSale]],"Manual")) -> 0 | X29: =(SUMIFS(msi[[#All],[CASH]],msi[[#All],[DATE]],$A29,msi[[#All],[Manual /OutSale]],"Manual"))-(SUMIFS(MRet[[#All],[CASH]],MRet[[#All],[DATE]],$A29,MRet[[#All],[Manual/ OutSale]],"Manual")) -> 0 | Y29: =D29-M29-N29+O29+Q29+R29-S29-T29-U29-V29-W29 -> 0 | Z29: =X29-Y29 -> 0
